Workbook

Sheet โครงการ
M1: สถานะ การกรอกข้อมูล | N1: =SUM(O7,O8,O9,O10,O13,O14,O26,O28,N32,O32,O36,O39,O51,O62,O87)
B2: แบบคำของบประมาณโครงการปฏิบัติการ ประจำปีงบประมาณ พ.ศ. 2570
B4: หน่วยงาน | D4: =IFERROR(VLOOKUP(D9,ListCost_Center!A:B,2,0),"") | M4: สีเขียว=กรอกข้อมูลครบถ้วน
B5: รายละเอียดข้อมูลโครงการ | M5: สีแดง=กรอกข้อมูลไม่ครบถ้วน
B6: 1 | C6: รหัสโครงการ | D6: =IFERROR(__xludf.DUMMYFUNCTION("VLOOKUP(D7,IMPORTRANGE(REF!$B$2,""FA!D:F""),3,0)"),"#N/A") | M6: คำอธิบายการกรอกแบบฟอร์ม-โครงการ
B7: 2 | C7: ชื่อโครงการ | D7: โครงการสร้างเครือข่ายระบบนิเวศนวัตกรรมและเทคโนโลยีดิจิทัล | O7: =IF(D7="",0,1)
B8: 3 | C8: ชื่อโครงการ (ย่อ) | D8: เครือข่ายนวัตกรรม ADT | G8: =IFS(D8="","ระบุไม่เกิน 25 ตัวอักษร",LEN(D8)<=25,LEN(D8)&" ตัวอักษร") | K8: =LEN(D8) | O8: =IF(D8="",0,1)
B9: 4 | C9: รหัสหน่วยงาน | D9: 11130000 | E9: =IFERROR(VLOOKUP(D9,ListCost_Center!A:B,2,0),"โปรดระบุ") | O9: =IF(D9="",0,1)
B10: 5 | C10: ประเภทโครงการ | D10: พัฒนาสำนักวิชา | F10: =IF(D10="อื่น ๆ","โปรดระบุประเภท","") | O10: =IF(D10="อื่น ๆ",IF(G10<>"",1,0),IF(D10="",0,1))
B12: 6 | C12: ความเชื่อมโยงของโครงการกับ (ร่าง)แผนพัฒนามหาวิทยาลัยแม่ฟ้าหลวง ฉบับที่ 6 (พ.ศ. 2570-2574)
B13: 6.1 | C13: กลยุทธ์ | D13: กลยุทธ์ 1.4 พัฒนาเครือข่ายความร่วมมือ | J13: =IF(D13="","โปรดระบุ","") | O13: =IF(D13="",0,1)
B14: 6.2 | C14: ตัวชี้วัดกระบวนการ | D14: X1.11 การมีส่วนร่วมของเครือข่ายพันธมิตร (Partner Engagement) | J14: =IF(D13="","",IF(D14="","โปรดระบุ","")) | O14: =IF(D14="",0,1)
C15: ประเด็นยุทธศาสตร์ | D15: {=XLOOKUP(D14,dropdown_plan6!R:R,dropdown_plan6!J:J,"")}
C16: ยุทธศาสตร์ | D16: {=XLOOKUP(D14,dropdown_plan6!R:R,dropdown_plan6!C:C,"")}
B18: 7 | C18: ความเชื่อมโยงของโครงการกับหัวข้ออื่น ๆ (เลือกได้มากกว่า 1 หัวข้อ)
B19: 7.1 | C19: ประเด็นความเสี่ยงของมหาวิทยาลัย | D19: ความสามารถในการพัฒนาบุคลากรให้สามารถปฏิบัติงานได้ตามความคาดหวัง ปรับตัวได้ทันต่อการเปลี่ยนแปลง และสามารถขับเคลื่อนมหาวิทยาลัยเข้าสู่การแข่งขันในอนาคต | J19: =IFERROR(VLOOKUP(D19,#REF!,2,0),"")
B20: 7.2 | C20: ค่านิยมองค์กร [เลือกได้มากกว่า 1 ข้อ] | D20: Teamwork 'ด้วยกัน'
B21: 7.3 | C21: เป้าหมายการพัฒนาที่ยั่งยืน (SDGs) [เลือกได้มากกว่า 1 ข้อ] | D21: SDG9 อุตสาหกรรม นวัตกรรม และโครงสร้างพื้นฐาน (Industry, Innovation and Infrastructure)
B22: 7.4 | C22: แผนปฏิบัติการป้องกันการทุจริต | J22: =IFERROR(VLOOKUP(D22,'Listความเชื่อมโยง'!A:B,2,0),"")
B23: 7.5 | C23: แผนพัฒนาของหน่วยงาน (เช่น ตัวชี้วัดภายใต้แผนฯ) | H23: =IF(D23<>"","โปรดแนบรายละเอียด","") | J23: =IF(D23="","",IF(I23="","เช่น PDF หรือ ลิงก์เล่มแผนฯ",""))
B24: 7.6 | C24: แผนอื่น ๆ | H24: =IF(D24<>"","โปรดแนบรายละเอียด","") | J24: =IF(D24="","",IF(I24="","เช่น PDF หรือ ลิงก์เล่มแผนฯ",""))
H25: =IF(F26=TRUE,"โปรดระบุชื่อโครงการในปีงบประมาณ พ.ศ. 2569","")
B26: 8 | C26: สถานภาพโครงการ | D26: TRUE | E26: โครงการใหม่ | F26: FALSE | G26: โครงการเดิม | O26: =IF(F26=TRUE,IF(H26<>"",1,0),IF(D26=FALSE,0,1))
B28: 9 | C28: ระยะเวลาดำเนินโครงการ | D28: =IFERROR(DAYS(D30,D29),"โปรดระบุ") | E28: วัน | G28: วัน | H28: เดือน | I28: ปี | O28: =IF(D28="โปรดระบุ",0,1)
D29: =G29&"/"&H29&"/"&I29 | E29: =G29&"."&H29&"."&I29 | F29: เริ่มต้นดำเนินการ | G29: 01 | H29: 05 | I29: 2027
D30: =G30&"/"&H30&"/"&I30 | E30: =G30&"."&H30&"."&I30 | F30: สิ้นสุดดำเนินการ | G30: 30 | H30: 06 | I30: 2027
B32: 10 | C32: หัวหน้าโครงการ | D32: ผศ.ดร.ณชา ชอนดอมรงค์กุล | G32: E-mail : | H32: nacha.cho@mfu.ac.th | N32: =IF(D33="",1,0) | O32: =IF(H33="",1,0)
D33: =IF(D32="","โปรดระบุ","") | H33: =IFERROR(__xludf.DUMMYFUNCTION("IF(H32="""",""โปรดระบุ"",IF(REGEXMATCH(H32, ""@mfu.ac.th""),"""", ""**ข้อมูลไม่ถูกต้อง** กรุณาระบุเป็น @mfu.ac.th เท่านั้น""))"),"โปรดระบุ")
B35: 11 | C35: หลักการและเหตุผล (ความสำคัญของโครงการ และความเชื่อมโยงของโครงการสำคัญประจําปี แผนพัฒนามหาวิทยาลัย ประเด็นความเสี่ยง ค่านิยมองค์กร SDGs การป้องกันการทุจริต แผนพัฒนาของหน่วยงาน หรือแผนอื่น ๆ ที่เกี่ยวข้อง)
C36: สำนักวิชาเทคโนโลยีดิจิทัลประยุกต์มีเป้าหมายในการเป็นสำนักวิชาชั้นนำด้านเทคโนโลยีดิจิทัลในภูมิภาคอนุภูมิภาคลุ่มน้ำโขง โดยมีแผนจัดตั้ง Intelligence Innovation Hub (IIC) ซึ่งเป็นศูนย์นวัตกรรมปัญญาประดิษฐ์และหุ่นยนต์ งบประมาณ 200 ล้านบาท เพื่อเตรียมความพร้อมสำหรับข้อเสนอโครงการ IIC จึงจำเป็นต้องสร้างเครือข่ายพันธมิตรกับหน่วยงานด้านนวัตกรรมและเทคโนโลยีชั้นนำ เช่น True Digital Park, NIA, depa, AIS The StartUp รวมถึงสถาบันอุดมศึกษาในกรุงเทพมหานคร เพื่อแลกเปลี่ยนองค์ความรู้ สร้างความร่วมมือด้านการวิจัย การพัฒนาหลักสูตร และการสร้าง Startup Ecosystem นอกจากนี้ยังเป็นโอกาสในการสร้างเครือข่ายศิษย์เก่าที่ทำงานในภาคอุตสาหกรรมดิจิทัล เพื่อนำข้อมูลและแนวโน้มของตลาดแรงงานมาพัฒนาหลักสูตรและกิจกรรมทางวิชาการให้ทันสมัย สอดคล้องกับกลยุทธ์ที่ 1.4 พัฒนาเครือข่ายความร่วมมือ และ SDG9 อุตสาหกรรม นวัตกรรม และโครงสร้างพื้นฐาน | O36: =IF(C36="",0,1)
B38: 12 | C38: วัตถุประสงค์ของโครงการ
C39: เพื่อสร้างเครือข่ายความร่วมมือกับหน่วยงานด้านนวัตกรรมและเทคโนโลยีดิจิทัลชั้นนำในกรุงเทพมหานคร | O39: =IF(C39="",0,1)
C40: เพื่อศึกษาแนวทางการจัดตั้งและบริหาร Innovation Hub, Incubator และ Startup Ecosystem สำหรับนำมาประยุกต์ใช้กับ IIC
C41: เพื่อสร้างเครือข่ายศิษย์เก่าและภาคอุตสาหกรรมดิจิทัลสำหรับการพัฒนาหลักสูตรและความร่วมมือด้านการวิจัย
C42: เพื่อเก็บข้อมูลแนวโน้มของตลาดแรงงานและทักษะที่จำเป็นในอนาคตจากภาคอุตสาหกรรม
C43: เพื่อสร้างโอกาสในการลงนามบันทึกข้อตกลงความร่วมมือ (MoU) กับหน่วยงานพันธมิตร
B50: 13 | C50: กลุ่มเป้าหมาย
C51: อาจารย์ประจำหลักสูตรสำนักวิชาเทคโนโลยีดิจิทัลประยุกต์ จำนวน 24 คน | O51: =IF(C51="",0,1)
C52: ผู้บริหารสำนักวิชา จำนวน 2 คน
C53: พนักงานผู้ประสานงาน จำนวน 2 คน
...

Sheet Claude Cache
A1: ⚠️ SHEET RESERVED FOR =CLAUDE... FUNCTIONS. DO NOT EDIT! ⚠️
A2: Key | B2: Value | C2: Expiration

Sheet งบประมาณ
A2: แบบคำของบประมาณ โครงการปฏิบัติการ ประจำปีงบประมาณ พ.ศ. 2570
A4: หน่วยงาน | C4: ='โครงการ'!D4 | D4: ='โครงการ'!D9
A5: ='โครงการ'!D6 | C5: ='โครงการ'!D7
A6: รายละเอียดงบประมาณโครงการ | F6: {=XLOOKUP(D6,'Listคก.งาน'!K31:K49,'Listคก.งาน'!M31:M49,"")}
A7: ลำดับที่ | B7: รหัสรายการ งบประมาณ | C7: ชื่อรายการงบประมาณ | D7: ชื่อบัญชีงบประมาณ | E7: คำของบประมาณ (บาท) | F7: กลุ่มเป้าหมาย | H7: ระยะเวลา | J7: งบประมาณ (บาท) | K7: จำนวนครั้ง | L7: พิจารณางบประมาณ (บาท) | M7: กลุ่มเป้าหมาย | O7: ระยะเวลา | Q7: งบประมาณ (บาท) | R7: จำนวนครั้ง | S7: ความเห็นจาก ผู้ประสานงานงบประมาณ | T7: จัดสรรงบประมาณ (บาท) | U7: กลุ่มเป้าหมาย | W7: ระยะเวลา | Y7: งบประมาณ (บาท) | Z7: จำนวนครั้ง | AA7: ความเห็นจากคณะกรรมการ | AB7: แนบ Link เอกสารเพิ่มเติม | AC7: หมายเหตุ | AD7: งบประมาณ 2567 | AE7: งบประมาณ 2568 | AF7: งบประมาณ 2569 | AG7: USE | AH7: ปรับแผน
F8: จำนวน | G8: หน่วย | H8: จำนวน | I8: หน่วย | M8: จำนวน | N8: หน่วย | O8: จำนวน | P8: หน่วย | U8: จำนวน | V8: หน่วย | W8: จำนวน | X8: หน่วย
D9: งบประมาณรวมทั้งสิ้น | E9: =SUM(E11,E32,E53,E74,E95,E116,E137,E158,E179,E200,E221,E242,E263,E284,E305,E326,E347,E368,E389,E410) | L9: =SUM(L11,L32,L53,L74,L95,L116,L137,L158,L179,L200,L221,L242,L263,L284,L305,L326,L347,L368,L389,L410) | T9: =SUM(T11,T32,T53,T74,T95,T116,T137,T158,T179,T200,T221,T242,T263,T284,T305,T326,T347,T368,T389,T410)
A10: 1 | B10: 1 | C10: 1 | D10: 1 | E10: 1 | F10: 1 | G10: 1 | H10: 1 | I10: 1 | J10: 1 | K10: 1 | L10: 1 | M10: 1 | N10: 1 | O10: 1 | P10: 1 | Q10: 1 | R10: 1 | S10: 1 | T10: 1 | U10: 1 | V10: 1 | W10: 1 | X10: 1 | Y10: 1 | Z10: 1 | AA10: 1 | AB10: 1 | AC10: 1 | AD10: 1 | AE10: 1 | AF10: 1 | AG10: 1 | AH10: 1
A11: 1 | B11: =IFERROR(__xludf.DUMMYFUNCTION("VLOOKUP(C11,IMPORTRANGE(REF!$B$3,""FP!B:C""),2,0)"),"#N/A") | C11: กิจกรรมสร้างเครือข่ายระบบนิเวศนวัตกรรม กรุงเทพฯ | E11: 355000 | L11: =SUM(L12:L31) | T11: =SUM(T12:T31) | AG11: FALSE
A12: =$A11&"."&1 | C12: กิจกรรมสร้างเครือข่ายระบบนิเวศนวัตกรรม กรุงเทพฯ | D12: ค่ายานพาหนะเครื่องบินผู้บริหาร | E12: 11000 | F12: 2 | G12: คน | H12: 1 | I12: ครั้ง | J12: 5500 | L12: =ROUNDUP(IF(Q12=0,0,Q12)*IF(R12>0,R12,1)*IF(M12>0,M12,1)*IF(O12>0,O12,1),0) | M12: =F12 | N12: =G12 | O12: =H12 | P12: =I12 | Q12: =J12 | R12: =K12 | T12: =ROUNDUP(IF(Y12=0,0,Y12)*IF(Z12>0,Z12,1)*IF(U12>0,U12,1)*IF(W12>0,W12,1),0) | U12: =M12 | V12: =N12 | W12: =O12 | X12: =P12 | Y12: =Q12 | Z12: =R12
A13: =$A11&"."&2 | C13: กิจกรรมสร้างเครือข่ายระบบนิเวศนวัตกรรม กรุงเทพฯ | D13: ค่ายานพาหนะเครื่องบินอาจารย์ | E13: 132000 | F13: 24 | G13: คน | H13: 1 | I13: ครั้ง | J13: 5500 | L13: =ROUNDUP(IF(Q13=0,0,Q13)*IF(R13>0,R13,1)*IF(M13>0,M13,1)*IF(O13>0,O13,1),0) | M13: =F13 | N13: =G13 | O13: =H13 | P13: =I13 | Q13: =J13 | R13: =K13 | T13: =ROUNDUP(IF(Y13=0,0,Y13)*IF(Z13>0,Z13,1)*IF(U13>0,U13,1)*IF(W13>0,W13,1),0) | U13: =M13 | V13: =N13 | W13: =O13 | X13: =P13 | Y13: =Q13 | Z13: =R13
A14: =$A11&"."&3 | C14: กิจกรรมสร้างเครือข่ายระบบนิเวศนวัตกรรม กรุงเทพฯ | D14: ค่ายานพาหนะเครื่องบินพนักงาน | E14: 8000 | F14: 2 | G14: คน | H14: 1 | I14: ครั้ง | J14: 4000 | L14: =ROUNDUP(IF(Q14=0,0,Q14)*IF(R14>0,R14,1)*IF(M14>0,M14,1)*IF(O14>0,O14,1),0) | M14: =F14 | N14: =G14 | O14: =H14 | P14: =I14 | Q14: =J14 | R14: =K14 | T14: =ROUNDUP(IF(Y14=0,0,Y14)*IF(Z14>0,Z14,1)*IF(U14>0,U14,1)*IF(W14>0,W14,1),0) | U14: =M14 | V14: =N14 | W14: =O14 | X14: =P14 | Y14: =Q14 | Z14: =R14
A15: =$A11&"."&4 | C15: กิจกรรมสร้างเครือข่ายระบบนิเวศนวัตกรรม กรุงเทพฯ | D15: ค่าที่พักผู้บริหาร | E15: 9600 | F15: 2 | G15: คน | H15: 3 | I15: คืน | J15: 1600 | L15: =ROUNDUP(IF(Q15=0,0,Q15)*IF(R15>0,R15,1)*IF(M15>0,M15,1)*IF(O15>0,O15,1),0) | M15: =F15 | N15: =G15 | O15: =H15 | P15: =I15 | Q15: =J15 | R15: =K15 | T15: =ROUNDUP(IF(Y15=0,0,Y15)*IF(Z15>0,Z15,1)*IF(U15>0,U15,1)*IF(W15>0,W15,1),0) | U15: =M15 | V15: =N15 | W15: =O15 | X15: =P15 | Y15: =Q15 | Z15: =R15
A16: =$A11&"."&5 | C16: กิจกรรมสร้างเครือข่ายระบบนิเวศนวัตกรรม กรุงเทพฯ | D16: ค่าที่พักอาจารย์ | E16: 115200 | F16: 24 | G16: คน | H16: 3 | I16: คืน | J16: 1600 | L16: =ROUNDUP(IF(Q16=0,0,Q16)*IF(R16>0,R16,1)*IF(M16>0,M16,1)*IF(O16>0,O16,1),0) | M16: =F16 | N16: =G16 | O16: =H16 | P16: =I16 | Q16: =J16 | R16: =K16 | T16: =ROUNDUP(IF(Y16=0,0,Y16)*IF(Z16>0,Z16,1)*IF(U16>0,U16,1)*IF(W16>0,W16,1),0) | U16: =M16 | V16: =N16 | W16: =O16 | X16: =P16 | Y16: =Q16 | Z16: =R16
A17: =$A11&"."&6 | C17: กิจกรรมสร้างเครือข่ายระบบนิเวศนวัตกรรม กรุงเทพฯ | D17: ค่าที่พักพนักงาน | E17: 8400 | F17: 2 | G17: คน | H17: 3 | I17: คืน | J17: 1400 | L17: =ROUNDUP(IF(Q17=0,0,Q17)*IF(R17>0,R17,1)*IF(M17>0,M17,1)*IF(O17>0,O17,1),0) | M17: =F17 | N17: =G17 | O17: =H17 | P17: =I17 | Q17: =J17 | R17: =K17 | T17: =ROUNDUP(IF(Y17=0,0,Y17)*IF(Z17>0,Z17,1)*IF(U17>0,U17,1)*IF(W17>0,W17,1),0) | U17: =M17 | V17: =N17 | W17: =O17 | X17: =P17 | Y17: =Q17 | Z17: =R17
A18: =$A11&"."&7 | C18: กิจกรรมสร้างเครือข่ายระบบนิเวศนวัตกรรม กรุงเทพฯ | D18: ค่าเบี้ยเลี้ยงผู้บริหาร | E18: 2100 | F18: 2 | G18: คน | H18: 3 | I18: วัน | J18: 350 | L18: =ROUNDUP(IF(Q18=0,0,Q18)*IF(R18>0,R18,1)*IF(M18>0,M18,1)*IF(O18>0,O18,1),0) | M18: =F18 | N18: =G18 | O18: =H18 | P18: =I18 | Q18: =J18 | R18: =K18 | T18: =ROUNDUP(IF(Y18=0,0,Y18)*IF(Z18>0,Z18,1)*IF(U18>0,U18,1)*IF(W18>0,W18,1),0) | U18: =M18 | V18: =N18 | W18: =O18 | X18: =P18 | Y18: =Q18 | Z18: =R18
A19: =$A11&"."&8 | C19: กิจกรรมสร้างเครือข่ายระบบนิเวศนวัตกรรม กรุงเทพฯ | D19: ค่าเบี้ยเลี้ยงอาจารย์ | E19: 25200 | F19: 24 | G19: คน | H19: 3 | I19: วัน | J19: 350 | L19: =ROUNDUP(IF(Q19=0,0,Q19)*IF(R19>0,R19,1)*IF(M19>0,M19,1)*IF(O19>0,O19,1),0) | M19: =F19 | N19: =G19 | O19: =H19 | P19: =I19 | Q19: =J19 | R19: =K19 | T19: =ROUNDUP(IF(Y19=0,0,Y19)*IF(Z19>0,Z19,1)*IF(U19>0,U19,1)*IF(W19>0,W19,1),0) | U19: =M19 | V19: =N19 | W19: =O19 | X19: =P19 | Y19: =Q19 | Z19: =R19
A20: =$A11&"."&9 | C20: กิจกรรมสร้างเครือข่ายระบบนิเวศนวัตกรรม กรุงเทพฯ | D20: ค่าเบี้ยเลี้ยงพนักงาน | E20: 1500 | F20: 2 | G20: คน | H20: 3 | I20: วัน | J20: 250 | L20: =ROUNDUP(IF(Q20=0,0,Q20)*IF(R20>0,R20,1)*IF(M20>0,M20,1)*IF(O20>0,O20,1),0) | M20: =F20 | N20: =G20 | O20: =H20 | P20: =I20 | Q20: =J20 | R20: =K20 | T20: =ROUNDUP(IF(Y20=0,0,Y20)*IF(Z20>0,Z20,1)*IF(U20>0,U20,1)*IF(W20>0,W20,1),0) | U20: =M20 | V20: =N20 | W20: =O20 | X20: =P20 | Y20: =Q20 | Z20: =R20
A21: =$A11&"."&10 | C21: กิจกรรมสร้างเครือข่ายระบบนิเวศนวัตกรรม กรุงเทพฯ | D21: ค่าเช่าเหมาบริการ-ยานพาหนะ | E21: 24000 | F21: 3 | G21: คัน | H21: 4 | I21: วัน | J21: 2000 | L21: =ROUNDUP(IF(Q21=0,0,Q21)*IF(R21>0,R21,1)*IF(M21>0,M21,1)*IF(O21>0,O21,1),0) | M21: =F21 | N21: =G21 | O21: =H21 | P21: =I21 | Q21: =J21 | R21: =K21 | T21: =ROUNDUP(IF(Y21=0,0,Y21)*IF(Z21>0,Z21,1)*IF(U21>0,U21,1)*IF(W21>0,W21,1),0) | U21: =M21 | V21: =N21 | W21: =O21 | X21: =P21 | Y21: =Q21 | Z21: =R21
A22: =$A11&"."&11 | C22: กิจกรรมสร้างเครือข่ายระบบนิเวศนวัตกรรม กรุงเทพฯ | D22: ค่าวัสดุเชื้อเพลิงและหล่อลื่น | E22: 18000 | F22: 3 | G22: คัน | H22: 4 | I22: วัน | J22: 1500 | L22: =ROUNDUP(IF(Q22=0,0,Q22)*IF(R22>0,R22,1)*IF(M22>0,M22,1)*IF(O22>0,O22,1),0) | M22: =F22 | N22: =G22 | O22: =H22 | P22: =I22 | Q22: =J22 | R22: =K22 | T22: =ROUNDUP(IF(Y22=0,0,Y22)*IF(Z22>0,Z22,1)*IF(U22>0,U22,1)*IF(W22>0,W22,1),0) | U22: =M22 | V22: =N22 | W22: =O22 | X22: =P22 | Y22: =Q22 | Z22: =R22
A23: =$A11&"."&12 | C23: =$C$11 | E23: =ROUNDUP(IF(J23=0,0,J23)*IF(K23>0,K23,1)*IF(F23>0,F23,1)*IF(H23>0,H23,1),0) | L23: =ROUNDUP(IF(Q23=0,0,Q23)*IF(R23>0,R23,1)*IF(M23>0,M23,1)*IF(O23>0,O23,1),0) | M23: =F23 | N23: =G23 | O23: =H23 | P23: =I23 | Q23: =J23 | R23: =K23 | T23: =ROUNDUP(IF(Y23=0,0,Y23)*IF(Z23>0,Z23,1)*IF(U23>0,U23,1)*IF(W23>0,W23,1),0) | U23: =M23 | V23: =N23 | W23: =O23 | X23: =P23 | Y23: =Q23 | Z23: =R23
A24: =$A11&"."&13 | C24: =$C$11 | E24: =ROUNDUP(IF(J24=0,0,J24)*IF(K24>0,K24,1)*IF(F24>0,F24,1)*IF(H24>0,H24,1),0) | L24: =ROUNDUP(IF(Q24=0,0,Q24)*IF(R24>0,R24,1)*IF(M24>0,M24,1)*IF(O24>0,O24,1),0) | M24: =F24 | N24: =G24 | O24: =H24 | P24: =I24 | Q24: =J24 | R24: =K24 | T24: =ROUNDUP(IF(Y24=0,0,Y24)*IF(Z24>0,Z24,1)*IF(U24>0,U24,1)*IF(W24>0,W24,1),0) | U24: =M24 | V24: =N24 | W24: =O24 | X24: =P24 | Y24: =Q24 | Z24: =R24
A25: =$A11&"."&14 | C25: =$C$11 | E25: =ROUNDUP(IF(J25=0,0,J25)*IF(K25>0,K25,1)*IF(F25>0,F25,1)*IF(H25>0,H25,1),0) | L25: =ROUNDUP(IF(Q25=0,0,Q25)*IF(R25>0,R25,1)*IF(M25>0,M25,1)*IF(O25>0,O25,1),0) | M25: =F25 | N25: =G25 | O25: =H25 | P25: =I25 | Q25: =J25 | R25: =K25 | T25: =ROUNDUP(IF(Y25=0,0,Y25)*IF(Z25>0,Z25,1)*IF(U25>0,U25,1)*IF(W25>0,W25,1),0) | U25: =M25 | V25: =N25 | W25: =O25 | X25: =P25 | Y25: =Q25 | Z25: =R25
A26: =$A11&"."&15 | C26: =$C$11 | E26: =ROUNDUP(IF(J26=0,0,J26)*IF(K26>0,K26,1)*IF(F26>0,F26,1)*IF(H26>0,H26,1),0) | L26: =ROUNDUP(IF(Q26=0,0,Q26)*IF(R26>0,R26,1)*IF(M26>0,M26,1)*IF(O26>0,O26,1),0) | M26: =F26 | N26: =G26 | O26: =H26 | P26: =I26 | Q26: =J26 | R26: =K26 | T26: =ROUNDUP(IF(Y26=0,0,Y26)*IF(Z26>0,Z26,1)*IF(U26>0,U26,1)*IF(W26>0,W26,1),0) | U26: =M26 | V26: =N26 | W26: =O26 | X26: =P26 | Y26: =Q26 | Z26: =R26
A27: =$A11&"."&16 | C27: =$C$11 | E27: =ROUNDUP(IF(J27=0,0,J27)*IF(K27>0,K27,1)*IF(F27>0,F27,1)*IF(H27>0,H27,1),0) | L27: =ROUNDUP(IF(Q27=0,0,Q27)*IF(R27>0,R27,1)*IF(M27>0,M27,1)*IF(O27>0,O27,1),0) | M27: =F27 | N27: =G27 | O27: =H27 | P27: =I27 | Q27: =J27 | R27: =K27 | T27: =ROUNDUP(IF(Y27=0,0,Y27)*IF(Z27>0,Z27,1)*IF(U27>0,U27,1)*IF(W27>0,W27,1),0) | U27: =M27 | V27: =N27 | W27: =O27 | X27: =P27 | Y27: =Q27 | Z27: =R27
A28: =$A11&"."&17 | C28: =$C$11 | E28: =ROUNDUP(IF(J28=0,0,J28)*IF(K28>0,K28,1)*IF(F28>0,F28,1)*IF(H28>0,H28,1),0) | L28: =ROUNDUP(IF(Q28=0,0,Q28)*IF(R28>0,R28,1)*IF(M28>0,M28,1)*IF(O28>0,O28,1),0) | M28: =F28 | N28: =G28 | O28: =H28 | P28: =I28 | Q28: =J28 | R28: =K28 | T28: =ROUNDUP(IF(Y28=0,0,Y28)*IF(Z28>0,Z28,1)*IF(U28>0,U28,1)*IF(W28>0,W28,1),0) | U28: =M28 | V28: =N28 | W28: =O28 | X28: =P28 | Y28: =Q28 | Z28: =R28
A29: =$A11&"."&18 | C29: =$C$11 | E29: =ROUNDUP(IF(J29=0,0,J29)*IF(K29>0,K29,1)*IF(F29>0,F29,1)*IF(H29>0,H29,1),0) | L29: =ROUNDUP(IF(Q29=0,0,Q29)*IF(R29>0,R29,1)*IF(M29>0,M29,1)*IF(O29>0,O29,1),0) | M29: =F29 | N29: =G29 | O29: =H29 | P29: =I29 | Q29: =J29 | R29: =K29 | T29: =ROUNDUP(IF(Y29=0,0,Y29)*IF(Z29>0,Z29,1)*IF(U29>0,U29,1)*IF(W29>0,W29,1),0) | U29: =M29 | V29: =N29 | W29: =O29 | X29: =P29 | Y29: =Q29 | Z29: =R29
A30: =$A11&"."&19 | C30: =$C$11 | E30: =ROUNDUP(IF(J30=0,0,J30)*IF(K30>0,K30,1)*IF(F30>0,F30,1)*IF(H30>0,H30,1),0) | L30: =ROUNDUP(IF(Q30=0,0,Q30)*IF(R30>0,R30,1)*IF(M30>0,M30,1)*IF(O30>0,O30,1),0) | M30: =F30 | N30: =G30 | O30: =H30 | P30: =I30 | Q30: =J30 | R30: =K30 | T30: =ROUNDUP(IF(Y30=0,0,Y30)*IF(Z30>0,Z30,1)*IF(U30>0,U30,1)*IF(W30>0,W30,1),0) | U30: =M30 | V30: =N30 | W30: =O30 | X30: =P30 | Y30: =Q30 | Z30: =R30
A31: =$A11&"."&20 | C31: =$C$11 | E31: =ROUNDUP(IF(J31=0,0,J31)*IF(K31>0,K31,1)*IF(F31>0,F31,1)*IF(H31>0,H31,1),0) | L31: =ROUNDUP(IF(Q31=0,0,Q31)*IF(R31>0,R31,1)*IF(M31>0,M31,1)*IF(O31>0,O31,1),0) | M31: =F31 | N31: =G31 | O31: =H31 | P31: =I31 | Q31: =J31 | R31: =K31 | T31: =ROUNDUP(IF(Y31=0,0,Y31)*IF(Z31>0,Z31,1)*IF(U31>0,U31,1)*IF(W31>0,W31,1),0) | U31: =M31 | V31: =N31 | W31: =O31 | X31: =P31 | Y31: =Q31 | Z31: =R31
A32: 2 | B32: =IFERROR(__xludf.DUMMYFUNCTION("VLOOKUP(C32,IMPORTRANGE(REF!$B$3,""FP!B:C""),2,0)"),"#N/A") | C32: กิจกรรมสร้างเครือข่ายศิษย์เก่าและอุตสาหกรรม | E32: 49000 | L32: =SUM(L33:L52) | T32: =SUM(T33:T52) | AG32: FALSE
A33: =$A32&"."&1 | C33: กิจกรรมสร้างเครือข่ายศิษย์เก่าและอุตสาหกรรม | D33: ค่าอาหารและเครื่องดื่ม (ศิษย์เก่า/อุตสาหกรรม) | E33: 21500 | F33: 50 | G33: คน | H33: 1 | I33: วัน | J33: 430 | L33: =ROUNDUP(IF(Q33=0,0,Q33)*IF(R33>0,R33,1)*IF(M33>0,M33,1)*IF(O33>0,O33,1),0) | M33: =F33 | N33: =G33 | O33: =H33 | P33: =I33 | Q33: =J33 | R33: =K33 | T33: =ROUNDUP(IF(Y33=0,0,Y33)*IF(Z33>0,Z33,1)*IF(U33>0,U33,1)*IF(W33>0,W33,1),0) | U33: =M33 | V33: =N33 | W33: =O33 | X33: =P33 | Y33: =Q33 | Z33: =R33
A34: =$A32&"."&2 | C34: กิจกรรมสร้างเครือข่ายศิษย์เก่าและอุตสาหกรรม | D34: ค่าอาหารและเครื่องดื่มผู้บริหาร | E34: 860 | F34: 2 | G34: คน | H34: 1 | I34: วัน | J34: 430 | L34: =ROUNDUP(IF(Q34=0,0,Q34)*IF(R34>0,R34,1)*IF(M34>0,M34,1)*IF(O34>0,O34,1),0) | M34: =F34 | N34: =G34 | O34: =H34 | P34: =I34 | Q34: =J34 | R34: =K34 | T34: =ROUNDUP(IF(Y34=0,0,Y34)*IF(Z34>0,Z34,1)*IF(U34>0,U34,1)*IF(W34>0,W34,1),0) | U34: =M34 | V34: =N34 | W34: =O34 | X34: =P34 | Y34: =Q34 | Z34: =R34
A35: =$A32&"."&3 | C35: กิจกรรมสร้างเครือข่ายศิษย์เก่าและอุตสาหกรรม | D35: ค่าอาหารและเครื่องดื่มอาจารย์ | E35: 10320 | F35: 24 | G35: คน | H35: 1 | I35: วัน | J35: 430 | L35: =ROUNDUP(IF(Q35=0,0,Q35)*IF(R35>0,R35,1)*IF(M35>0,M35,1)*IF(O35>0,O35,1),0) | M35: =F35 | N35: =G35 | O35: =H35 | P35: =I35 | Q35: =J35 | R35: =K35 | T35: =ROUNDUP(IF(Y35=0,0,Y35)*IF(Z35>0,Z35,1)*IF(U35>0,U35,1)*IF(W35>0,W35,1),0) | U35: =M35 | V35: =N35 | W35: =O35 | X35: =P35 | Y35: =Q35 | Z35: =R35
A36: =$A32&"."&4 | C36: กิจกรรมสร้างเครือข่ายศิษย์เก่าและอุตสาหกรรม | D36: ค่าอาหารและเครื่องดื่มพนักงาน | E36: 860 | F36: 2 | G36: คน | H36: 1 | I36: วัน | J36: 430 | L36: =ROUNDUP(IF(Q36=0,0,Q36)*IF(R36>0,R36,1)*IF(M36>0,M36,1)*IF(O36>0,O36,1),0) | M36: =F36 | N36: =G36 | O36: =H36 | P36: =I36 | Q36: =J36 | R36: =K36 | T36: =ROUNDUP(IF(Y36=0,0,Y36)*IF(Z36>0,Z36,1)*IF(U36>0,U36,1)*IF(W36>0,W36,1),0) | U36: =M36 | V36: =N36 | W36: =O36 | X36: =P36 | Y36: =Q36 | Z36: =R36
A37: =$A32&"."&5 | C37: กิจกรรมสร้างเครือข่ายศิษย์เก่าและอุตสาหกรรม | D37: ค่าบำรุงสถานที่/เครื่องมืออุปกรณ์ | E37: 10000 | F37: 1 | G37: ห้อง | H37: 1 | I37: วัน | J37: 10000 | L37: =ROUNDUP(IF(Q37=0,0,Q37)*IF(R37>0,R37,1)*IF(M37>0,M37,1)*IF(O37>0,O37,1),0) | M37: =F37 | N37: =G37 | O37: =H37 | P37: =I37 | Q37: =J37 | R37: =K37 | T37: =ROUNDUP(IF(Y37=0,0,Y37)*IF(Z37>0,Z37,1)*IF(U37>0,U37,1)*IF(W37>0,W37,1),0) | U37: =M37 | V37: =N37 | W37: =O37 | X37: =P37 | Y37: =Q37 | Z37: =R37
A38: =$A32&"."&6 | C38: กิจกรรมสร้างเครือข่ายศิษย์เก่าและอุตสาหกรรม | D38: ค่าวัสดุอุปกรณ์ | E38: 5460 | F38: 1 | G38: ชุด | H38: 1 | I38: ครั้ง | J38: 5460 | L38: =ROUNDUP(IF(Q38=0,0,Q38)*IF(R38>0,R38,1)*IF(M38>0,M38,1)*IF(O38>0,O38,1),0) | M38: =F38 | N38: =G38 | O38: =H38 | P38: =I38 | Q38: =J38 | R38: =K38 | T38: =ROUNDUP(IF(Y38=0,0,Y38)*IF(Z38>0,Z38,1)*IF(U38>0,U38,1)*IF(W38>0,W38,1),0) | U38: =M38 | V38: =N38 | W38: =O38 | X38: =P38 | Y38: =Q38 | Z38: =R38
A39: =$A32&"."&7 | C39: =$C$32 | E39: =ROUNDUP(IF(J39=0,0,J39)*IF(K39>0,K39,1)*IF(F39>0,F39,1)*IF(H39>0,H39,1),0) | L39: =ROUNDUP(IF(Q39=0,0,Q39)*IF(R39>0,R39,1)*IF(M39>0,M39,1)*IF(O39>0,O39,1),0) | M39: =F39 | N39: =G39 | O39: =H39 | P39: =I39 | Q39: =J39 | R39: =K39 | T39: =ROUNDUP(IF(Y39=0,0,Y39)*IF(Z39>0,Z39,1)*IF(U39>0,U39,1)*IF(W39>0,W39,1),0) | U39: =M39 | V39: =N39 | W39: =O39 | X39: =P39 | Y39: =Q39 | Z39: =R39
A40: =$A32&"."&8 | C40: =$C$32 | E40: =ROUNDUP(IF(J40=0,0,J40)*IF(K40>0,K40,1)*IF(F40>0,F40,1)*IF(H40>0,H40,1),0) | L40: =ROUNDUP(IF(Q40=0,0,Q40)*IF(R40>0,R40,1)*IF(M40>0,M40,1)*IF(O40>0,O40,1),0) | M40: =F40 | N40: =G40 | O40: =H40 | P40: =I40 | Q40: =J40 | R40: =K40 | T40: =ROUNDUP(IF(Y40=0,0,Y40)*IF(Z40>0,Z40,1)*IF(U40>0,U40,1)*IF(W40>0,W40,1),0) | U40: =M40 | V40: =N40 | W40: =O40 | X40: =P40 | Y40: =Q40 | Z40: =R40
A41: =$A32&"."&9 | C41: =$C$32 | E41: =ROUNDUP(IF(J41=0,0,J41)*IF(K41>0,K41,1)*IF(F41>0,F41,1)*IF(H41>0,H41,1),0) | L41: =ROUNDUP(IF(Q41=0,0,Q41)*IF(R41>0,R41,1)*IF(M41>0,M41,1)*IF(O41>0,O41,1),0) | M41: =F41 | N41: =G41 | O41: =H41 | P41: =I41 | Q41: =J41 | R41: =K41 | T41: =ROUNDUP(IF(Y41=0,0,Y41)*IF(Z41>0,Z41,1)*IF(U41>0,U41,1)*IF(W41>0,W41,1),0) | U41: =M41 | V41: =N41 | W41: =O41 | X41: =P41 | Y41: =Q41 | Z41: =R41
A42: =$A32&"."&10 | C42: =$C$32 | E42: =ROUNDUP(IF(J42=0,0,J42)*IF(K42>0,K42,1)*IF(F42>0,F42,1)*IF(H42>0,H42,1),0) | L42: =ROUNDUP(IF(Q42=0,0,Q42)*IF(R42>0,R42,1)*IF(M42>0,M42,1)*IF(O42>0,O42,1),0) | M42: =F42 | N42: =G42 | O42: =H42 | P42: =I42 | Q42: =J42 | R42: =K42 | T42: =ROUNDUP(IF(Y42=0,0,Y42)*IF(Z42>0,Z42,1)*IF(U42>0,U42,1)*IF(W42>0,W42,1),0) | U42: =M42 | V42: =N42 | W42: =O42 | X42: =P42 | Y42: =Q42 | Z42: =R42
...

Sheet แผนดำเนินงาน-แผนใช้จ่าย
A2: แผนการดำเนินงานและแผนการใช้จ่ายงบประมาณ | E2: แผนการดำเนินงาน = เลือกเดือนที่จะดำเนินงาน | แผนการใช้จ่าย = ระบุวงเงินที่คาดว่าจะใช้จ่ายตามเดือน
A3: รหัสรายการ งบประมาณ | B3: ชื่อรายการงบประมาณ | C3: งบประมาณ (บาท) | D3: แผน | E3: ต.ค.69 | F3: พ.ย.69 | G3: ธ.ค.69 | H3: ม.ค.70 | I3: ก.พ.70 | J3: มี.ค.70 | K3: เม.ย.70 | L3: พ.ค.70 | M3: มิ.ย.70 | N3: ก.ค.70 | O3: ส.ค.70 | P3: ก.ย.70 | Q3: หมายเหตุ
A4: =IFERROR(__xludf.DUMMYFUNCTION("IFERROR(QUERY('รายการงบประมาณ'!$A$2:$F$2,""SELECT A,B,E""))"),"") | D4: แผนการดำเนินงาน | E4: FALSE | F4: FALSE | G4: FALSE | H4: FALSE | I4: FALSE | J4: FALSE | K4: FALSE | L4: FALSE | M4: FALSE | N4: FALSE | O4: FALSE | P4: FALSE
A5: =A4 | B5: =B4 | C5: =C4 | D5: แผนการใช้จ่าย | R5: =IF(C5=0,"",IFS(C5>SUM(E5:P5),"วงเงินขาด "&SUM(E5:P5)-C5,C5<SUM(E5:P5),"วงเงินเกิน "&SUM(E5:P5)-C5,C5=SUM(E5:P5),""))
A6: =IFERROR(__xludf.DUMMYFUNCTION("IFERROR(QUERY('รายการงบประมาณ'!$A$3:$F$3,""SELECT A,B,E""))"),"") | D6: แผนการดำเนินงาน | E6: FALSE | F6: FALSE | G6: FALSE | H6: FALSE | I6: FALSE | J6: FALSE | K6: FALSE | L6: FALSE | M6: FALSE | N6: FALSE | O6: FALSE | P6: FALSE
A7: =A6 | B7: =B6 | C7: =C6 | D7: แผนการใช้จ่าย | R7: =IF(C7=0,"",IFS(C7>SUM(E7:P7),"วงเงินขาด "&SUM(E7:P7)-C7,C7<SUM(E7:P7),"วงเงินเกิน "&SUM(E7:P7)-C7,C7=SUM(E7:P7),""))
A8: =IFERROR(__xludf.DUMMYFUNCTION("IFERROR(QUERY('รายการงบประมาณ'!$A$4:$F$4,""SELECT A,B,E""))"),"") | D8: แผนการดำเนินงาน | E8: FALSE | F8: FALSE | G8: FALSE | H8: FALSE | I8: FALSE | J8: FALSE | K8: FALSE | L8: FALSE | M8: FALSE | N8: FALSE | O8: FALSE | P8: FALSE
A9: =A8 | B9: =B8 | C9: =C8 | D9: แผนการใช้จ่าย | R9: =IF(C9=0,"",IFS(C9>SUM(E9:P9),"วงเงินขาด "&SUM(E9:P9)-C9,C9<SUM(E9:P9),"วงเงินเกิน "&SUM(E9:P9)-C9,C9=SUM(E9:P9),""))
A10: =IFERROR(__xludf.DUMMYFUNCTION("IFERROR(QUERY('รายการงบประมาณ'!$A$5:$F$5,""SELECT A,B,E""))"),"") | D10: แผนการดำเนินงาน | E10: FALSE | F10: FALSE | G10: FALSE | H10: FALSE | I10: FALSE | J10: FALSE | K10: FALSE | L10: FALSE | M10: FALSE | N10: FALSE | O10: FALSE | P10: FALSE
A11: =A10 | B11: =B10 | C11: =C10 | D11: แผนการใช้จ่าย | R11: =IF(C11=0,"",IFS(C11>SUM(E11:P11),"วงเงินขาด "&SUM(E11:P11)-C11,C11<SUM(E11:P11),"วงเงินเกิน "&SUM(E11:P11)-C11,C11=SUM(E11:P11),""))
A12: =IFERROR(__xludf.DUMMYFUNCTION("IFERROR(QUERY('รายการงบประมาณ'!$A$6:$F$6,""SELECT A,B,E""))"),"") | D12: แผนการดำเนินงาน | E12: FALSE | F12: FALSE | G12: FALSE | H12: FALSE | I12: FALSE | J12: FALSE | K12: FALSE | L12: FALSE | M12: FALSE | N12: FALSE | O12: FALSE | P12: FALSE
A13: =A12 | B13: =B12 | C13: =C12 | D13: แผนการใช้จ่าย | R13: =IF(C13=0,"",IFS(C13>SUM(E13:P13),"วงเงินขาด "&SUM(E13:P13)-C13,C13<SUM(E13:P13),"วงเงินเกิน "&SUM(E13:P13)-C13,C13=SUM(E13:P13),""))
A14: =IFERROR(__xludf.DUMMYFUNCTION("IFERROR(QUERY('รายการงบประมาณ'!$A$7:$F$7,""SELECT A,B,E""))"),"") | D14: แผนการดำเนินงาน | E14: FALSE | F14: FALSE | G14: FALSE | H14: FALSE | I14: FALSE | J14: FALSE | K14: FALSE | L14: FALSE | M14: FALSE | N14: FALSE | O14: FALSE | P14: FALSE
A15: =A14 | B15: =B14 | C15: =C14 | D15: แผนการใช้จ่าย | R15: =IF(C15=0,"",IFS(C15>SUM(E15:P15),"วงเงินขาด "&SUM(E15:P15)-C15,C15<SUM(E15:P15),"วงเงินเกิน "&SUM(E15:P15)-C15,C15=SUM(E15:P15),""))
A16: =IFERROR(__xludf.DUMMYFUNCTION("IFERROR(QUERY('รายการงบประมาณ'!$A$8:$F$8,""SELECT A,B,E""))"),"") | D16: แผนการดำเนินงาน | E16: FALSE | F16: FALSE | G16: FALSE | H16: FALSE | I16: FALSE | J16: FALSE | K16: FALSE | L16: FALSE | M16: FALSE | N16: FALSE | O16: FALSE | P16: FALSE
A17: =A16 | B17: =B16 | C17: =C16 | D17: แผนการใช้จ่าย | R17: =IF(C17=0,"",IFS(C17>SUM(E17:P17),"วงเงินขาด "&SUM(E17:P17)-C17,C17<SUM(E17:P17),"วงเงินเกิน "&SUM(E17:P17)-C17,C17=SUM(E17:P17),""))
A18: =IFERROR(__xludf.DUMMYFUNCTION("IFERROR(QUERY('รายการงบประมาณ'!$A$9:$F$9,""SELECT A,B,E""))"),"") | D18: แผนการดำเนินงาน | E18: FALSE | F18: FALSE | G18: FALSE | H18: FALSE | I18: FALSE | J18: FALSE | K18: FALSE | L18: FALSE | M18: FALSE | N18: FALSE | O18: FALSE | P18: FALSE
A19: =A18 | B19: =B18 | C19: =C18 | D19: แผนการใช้จ่าย | R19: =IF(C19=0,"",IFS(C19>SUM(E19:P19),"วงเงินขาด "&SUM(E19:P19)-C19,C19<SUM(E19:P19),"วงเงินเกิน "&SUM(E19:P19)-C19,C19=SUM(E19:P19),""))
A20: =IFERROR(__xludf.DUMMYFUNCTION("IFERROR(QUERY('รายการงบประมาณ'!$A$10:$F$10,""SELECT A,B,E""))"),"") | D20: แผนการดำเนินงาน | E20: FALSE | F20: FALSE | G20: FALSE | H20: FALSE | I20: FALSE | J20: FALSE | K20: FALSE | L20: FALSE | M20: FALSE | N20: FALSE | O20: FALSE | P20: FALSE
A21: =A20 | B21: =B20 | C21: =C20 | D21: แผนการใช้จ่าย | R21: =IF(C21=0,"",IFS(C21>SUM(E21:P21),"วงเงินขาด "&SUM(E21:P21)-C21,C21<SUM(E21:P21),"วงเงินเกิน "&SUM(E21:P21)-C21,C21=SUM(E21:P21),""))
A22: =IFERROR(__xludf.DUMMYFUNCTION("IFERROR(QUERY('รายการงบประมาณ'!$A$11:$F$11,""SELECT A,B,E""))"),"") | D22: แผนการดำเนินงาน | E22: FALSE | F22: FALSE | G22: FALSE | H22: FALSE | I22: FALSE | J22: FALSE | K22: FALSE | L22: FALSE | M22: FALSE | N22: FALSE | O22: FALSE | P22: FALSE
A23: =A22 | B23: =B22 | C23: =C22 | D23: แผนการใช้จ่าย | R23: =IF(C23=0,"",IFS(C23>SUM(E23:P23),"วงเงินขาด "&SUM(E23:P23)-C23,C23<SUM(E23:P23),"วงเงินเกิน "&SUM(E23:P23)-C23,C23=SUM(E23:P23),""))
A24: =IFERROR(__xludf.DUMMYFUNCTION("IFERROR(QUERY('รายการงบประมาณ'!$A$12:$F$12,""SELECT A,B,E""))"),"") | D24: แผนการดำเนินงาน | E24: FALSE | F24: FALSE | G24: FALSE | H24: FALSE | I24: FALSE | J24: FALSE | K24: FALSE | L24: FALSE | M24: FALSE | N24: FALSE | O24: FALSE | P24: FALSE
A25: =A24 | B25: =B24 | C25: =C24 | D25: แผนการใช้จ่าย | R25: =IF(C25=0,"",IFS(C25>SUM(E25:P25),"วงเงินขาด "&SUM(E25:P25)-C25,C25<SUM(E25:P25),"วงเงินเกิน "&SUM(E25:P25)-C25,C25=SUM(E25:P25),""))
A26: =IFERROR(__xludf.DUMMYFUNCTION("IFERROR(QUERY('รายการงบประมาณ'!$A$13:$F$13,""SELECT A,B,E""))"),"") | D26: แผนการดำเนินงาน | E26: FALSE | F26: FALSE | G26: FALSE | H26: FALSE | I26: FALSE | J26: FALSE | K26: FALSE | L26: FALSE | M26: FALSE | N26: FALSE | O26: FALSE | P26: FALSE
A27: =A26 | B27: =B26 | C27: =C26 | D27: แผนการใช้จ่าย | R27: =IF(C27=0,"",IFS(C27>SUM(E27:P27),"วงเงินขาด "&SUM(E27:P27)-C27,C27<SUM(E27:P27),"วงเงินเกิน "&SUM(E27:P27)-C27,C27=SUM(E27:P27),""))
A28: =IFERROR(__xludf.DUMMYFUNCTION("IFERROR(QUERY('รายการงบประมาณ'!$A$14:$F$14,""SELECT A,B,E""))"),"") | D28: แผนการดำเนินงาน | E28: FALSE | F28: FALSE | G28: FALSE | H28: FALSE | I28: FALSE | J28: FALSE | K28: FALSE | L28: FALSE | M28: FALSE | N28: FALSE | O28: FALSE | P28: FALSE
A29: =A28 | B29: =B28 | C29: =C28 | D29: แผนการใช้จ่าย | R29: =IF(C29=0,"",IFS(C29>SUM(E29:P29),"วงเงินขาด "&SUM(E29:P29)-C29,C29<SUM(E29:P29),"วงเงินเกิน "&SUM(E29:P29)-C29,C29=SUM(E29:P29),""))
A30: =IFERROR(__xludf.DUMMYFUNCTION("IFERROR(QUERY('รายการงบประมาณ'!$A$15:$F$15,""SELECT A,B,E""))"),"") | D30: แผนการดำเนินงาน | E30: FALSE | F30: FALSE | G30: FALSE | H30: FALSE | I30: FALSE | J30: FALSE | K30: FALSE | L30: FALSE | M30: FALSE | N30: FALSE | O30: FALSE | P30: FALSE
A31: =A30 | B31: =B30 | C31: =C30 | D31: แผนการใช้จ่าย | R31: =IF(C31=0,"",IFS(C31>SUM(E31:P31),"วงเงินขาด "&SUM(E31:P31)-C31,C31<SUM(E31:P31),"วงเงินเกิน "&SUM(E31:P31)-C31,C31=SUM(E31:P31),""))
A32: =IFERROR(__xludf.DUMMYFUNCTION("IFERROR(QUERY('รายการงบประมาณ'!$A$16:$F$16,""SELECT A,B,E""))"),"") | D32: แผนการดำเนินงาน | E32: FALSE | F32: FALSE | G32: FALSE | H32: FALSE | I32: FALSE | J32: FALSE | K32: FALSE | L32: FALSE | M32: FALSE | N32: FALSE | O32: FALSE | P32: FALSE
A33: =A32 | B33: =B32 | C33: =C32 | D33: แผนการใช้จ่าย | R33: =IF(C33=0,"",IFS(C33>SUM(E33:P33),"วงเงินขาด "&SUM(E33:P33)-C33,C33<SUM(E33:P33),"วงเงินเกิน "&SUM(E33:P33)-C33,C33=SUM(E33:P33),""))
A34: =IFERROR(__xludf.DUMMYFUNCTION("IFERROR(QUERY('รายการงบประมาณ'!$A$17:$F$17,""SELECT A,B,E""))"),"") | D34: แผนการดำเนินงาน | E34: FALSE | F34: FALSE | G34: FALSE | H34: FALSE | I34: FALSE | J34: FALSE | K34: FALSE | L34: FALSE | M34: FALSE | N34: FALSE | O34: FALSE | P34: FALSE
A35: =A34 | B35: =B34 | C35: =C34 | D35: แผนการใช้จ่าย | R35: =IF(C35=0,"",IFS(C35>SUM(E35:P35),"วงเงินขาด "&SUM(E35:P35)-C35,C35<SUM(E35:P35),"วงเงินเกิน "&SUM(E35:P35)-C35,C35=SUM(E35:P35),""))
A36: =IFERROR(__xludf.DUMMYFUNCTION("IFERROR(QUERY('รายการงบประมาณ'!$A$18:$F$18,""SELECT A,B,E""))"),"") | D36: แผนการดำเนินงาน | E36: FALSE | F36: FALSE | G36: FALSE | H36: FALSE | I36: FALSE | J36: FALSE | K36: FALSE | L36: FALSE | M36: FALSE | N36: FALSE | O36: FALSE | P36: FALSE
A37: =A36 | B37: =B36 | C37: =C36 | D37: แผนการใช้จ่าย | R37: =IF(C37=0,"",IFS(C37>SUM(E37:P37),"วงเงินขาด "&SUM(E37:P37)-C37,C37<SUM(E37:P37),"วงเงินเกิน "&SUM(E37:P37)-C37,C37=SUM(E37:P37),""))
A38: =IFERROR(__xludf.DUMMYFUNCTION("IFERROR(QUERY('รายการงบประมาณ'!$A$19:$F$19,""SELECT A,B,E""))"),"") | D38: แผนการดำเนินงาน | E38: FALSE | F38: FALSE | G38: FALSE | H38: FALSE | I38: FALSE | J38: FALSE | K38: FALSE | L38: FALSE | M38: FALSE | N38: FALSE | O38: FALSE | P38: FALSE
A39: =A38 | B39: =B38 | C39: =C38 | D39: แผนการใช้จ่าย | R39: =IF(C39=0,"",IFS(C39>SUM(E39:P39),"วงเงินขาด "&SUM(E39:P39)-C39,C39<SUM(E39:P39),"วงเงินเกิน "&SUM(E39:P39)-C39,C39=SUM(E39:P39),""))
A40: =IFERROR(__xludf.DUMMYFUNCTION("IFERROR(QUERY('รายการงบประมาณ'!$A$20:$F$20,""SELECT A,B,E""))"),"") | D40: แผนการดำเนินงาน | E40: FALSE | F40: FALSE | G40: FALSE | H40: FALSE | I40: FALSE | J40: FALSE | K40: FALSE | L40: FALSE | M40: FALSE | N40: FALSE | O40: FALSE | P40: FALSE
A41: =A40 | B41: =B40 | C41: =C40 | D41: แผนการใช้จ่าย | R41: =IF(C41=0,"",IFS(C41>SUM(E41:P41),"วงเงินขาด "&SUM(E41:P41)-C41,C41<SUM(E41:P41),"วงเงินเกิน "&SUM(E41:P41)-C41,C41=SUM(E41:P41),""))
...

Sheet รายงานQ1
A7: แบบรายงานผลการดำเนินโครงการ ณ สิ้นสุดไตรมาส 1 ประจำปีงบประมาณ 2570
A8: หน่วยงาน | C8: ='โครงการ'!D4 | J8: คำอธิบายการกรอกแบบฟอร์ม
A9: ='โครงการ'!D6 | C9: ='โครงการ'!D7
A11: หัวหน้าโครงการ | C11: ='โครงการ'!D32 | F11: E-mail : @mfu | H11: ='โครงการ'!H32
A13: ชื่อผู้รายงานผล | F13: ผู้รายงานผลกรอกข้อมูลแล้วเสร็จ | J13: FALSE
A15: ณ สิ้นสุดไตรมาส ประเมินการดำเนินงานภาพรวมคิดเป็น | D15: ร้อยละ | E15: 0 | G15: =IFERROR(__xludf.DUMMYFUNCTION("IFERROR(SPARKLINE(E15,{""charttype"",""bar"";""color1"",""orenge"";""max"",100}),""โปรดระบุร้อยละการดำเนินงานเป็นตัวเลช"")"),"")
A17: หัวหน้าโครงการส่งรายงานผลการดำเนินงาน ณ สิ้นสุดไตรมาส 1 | E17: FALSE | G17: ว/ด/ป ที่ส่งรายงาน
A20: ผลการดำเนินงานรายกิจกรรม
A21: ลำดับที่ | B21: รหัสรายการ งบประมาณ | C21: ชื่อรายการงบประมาณ/ชื่อกิจกรรม | D21: สถานะ การดำเนินงาน | E21: อธิบายผลการดำเนินงานตามสถานะ (ให้ระบุว่า ณ สิ้นสุดไตรมาสมีการดำเนินงานอย่างไร)
A23: 1 | B23: =IFERROR(__xludf.DUMMYFUNCTION("QUERY('รายการงบประมาณ'!$A$2:$F80,""SELECT A,B WHERE E>0"")"),"#N/A")
A24: 2
A25: 3
A26: 4
A27: 5
A28: 6
A29: 7
A30: 8
A31: 9
A32: 10
A33: 11
A34: 12
A35: 13
... A42: 20
A43: คำอธิบาย สถานะการดำเนินงาน
A44: หมายเหตุ | B44: โปรดระบุตัวเลขสถานะการดำเนินงาน ในช่อง "สถานะการดำเนินงาน"
B45: 1 | C45: ไม่ได้ดำเนินงาน | D45: หมายถึง ถึงแผนที่จะต้องดำเนินงานแล้ว แต่ "ไม่ได้ดำเนินการ" เนื่องจากมีเหตุจำเป็น...
B46: 2 | C46: ไม่ถึงแผนที่กำหนด | D46: หมายถึง มีแผนการดำเนินงานในไตรมาสอื่น
B47: 3 | C47: อยู่ระหว่างการดำเนินงาน | D47: หมายถึง ดำเนินงานแล้ว แต่ยังไม่เเล้วเสร็จ หรือมีแผนดำเนินงานครั้งที่ 2/3/4
B48: 4 | C48: ดำเนินการแล้ว | D48: หมายถึง ดำเนินงานแล้วเสร็จ
A50: ผลการดำเนินงาน
A51: ตัวชี้วัดความสำเร็จของโครงการ | D51: หน่วยนับ | E51: แผน ปี 2570 | F51: ผล ปี 2570 | G51: การรายงานผล | I51: อธิบายผลการดำเนินงาน (รายงานผลเทียบแผน อย่างไร)
A53: เชิงปริมาณ | F53: ไตรมาส 1 | G53: ระบุได้ | H53: ระบุไม่ได้
A54: =IFERROR(__xludf.DUMMYFUNCTION("QUERY('โครงการ'!C65:J74,""SELECT C WHERE C IS NOT NULL"")"),"#N/A") | D54: =IFERROR(__xludf.DUMMYFUNCTION("QUERY('โครงการ'!C65:J74,""SELECT I,J WHERE C IS NOT NULL"")"),"#N/A") | G54: FALSE | H54: FALSE
G55: FALSE | H55: FALSE
G56: FALSE | H56: FALSE
G57: FALSE | H57: FALSE
G58: FALSE | H58: FALSE
G59: FALSE | H59: FALSE
G60: FALSE | H60: FALSE
G61: FALSE | H61: FALSE
...

Sheet รายงานQ2
A7: แบบรายงานผลการดำเนินโครงการ ณ สิ้นสุดไตรมาส 2 ประจำปีงบประมาณ 2570
A8: หน่วยงาน | C8: ='โครงการ'!D4 | J8: คำอธิบายการกรอกแบบฟอร์ม
A9: ='โครงการ'!D6 | C9: ='โครงการ'!D7
A11: หัวหน้าโครงการ | C11: ='รายงานQ1'!C11 | F11: E-mail : @mfu | H11: ='รายงานQ1'!H11
A13: ชื่อผู้รายงานผล | F13: ผู้รายงานผลกรอกข้อมูลแล้วเสร็จ | J13: FALSE
A15: ณ สิ้นสุดไตรมาส ประเมินการดำเนินงานภาพรวมคิดเป็น | D15: ร้อยละ | E15: 0 | G15: =IFERROR(__xludf.DUMMYFUNCTION("IFERROR(SPARKLINE(E15,{""charttype"",""bar"";""color1"",""orenge"";""max"",100}),""โปรดระบุร้อยละการดำเนินงานเป็นตัวเลช"")"),"")
A17: หัวหน้าโครงการส่งรายงานผลการดำเนินงาน ณ สิ้นสุดไตรมาส 2 | E17: FALSE | G17: ว/ด/ป ที่ส่งรายงาน
A20: ผลการดำเนินงานรายกิจกรรม
A21: ลำดับที่ | B21: รหัสรายการ งบประมาณ | C21: ชื่อรายการงบประมาณ/ชื่อกิจกรรม | D21: สถานะ การดำเนินงาน | E21: อธิบายผลการดำเนินงานตามสถานะ (ให้ระบุว่า ณ สิ้นสุดไตรมาสมีการดำเนินงานอย่างไร)
A23: 1 | B23: =IFERROR(__xludf.DUMMYFUNCTION("QUERY('รายการงบประมาณ'!$A$2:$F80,""SELECT A,B WHERE E>0"")"),"#N/A")
A24: 2
A25: 3
A26: 4
A27: 5
A28: 6
A29: 7
A30: 8
A31: 9
A32: 10
A33: 11
A34: 12
A35: 13
... A42: 20
A43: คำอธิบาย สถานะการดำเนินงาน
A44: หมายเหตุ | B44: โปรดระบุตัวเลขสถานะการดำเนินงาน ในช่อง "สถานะการดำเนินงาน"
B45: 1 | C45: ไม่ได้ดำเนินงาน | D45: หมายถึง ถึงแผนที่จะต้องดำเนินงานแล้ว แต่ "ไม่ได้ดำเนินการ" เนื่องจากมีเหตุจำเป็น...
B46: 2 | C46: ไม่ถึงแผนที่กำหนด | D46: หมายถึง มีแผนการดำเนินงานในไตรมาสอื่น
B47: 3 | C47: อยู่ระหว่างการดำเนินงาน | D47: หมายถึง ดำเนินงานแล้ว แต่ยังไม่เเล้วเสร็จ หรือมีแผนดำเนินงานครั้งที่ 2/3/4
B48: 4 | C48: ดำเนินการแล้ว | D48: หมายถึง ดำเนินงานแล้วเสร็จ
A50: ผลการดำเนินงาน
A51: ตัวชี้วัดความสำเร็จของโครงการ | D51: หน่วยนับ | E51: แผน ปี 2570 | F51: ผล ปี 2570 | G51: การรายงานผล | I51: อธิบายผลการดำเนินงาน (รายงานผลเทียบแผน อย่างไร)
A53: เชิงปริมาณ | F53: ไตรมาส 2 | G53: ระบุได้ | H53: ระบุไม่ได้
A54: =IFERROR(__xludf.DUMMYFUNCTION("QUERY('โครงการ'!C65:J74,""SELECT C WHERE C IS NOT NULL"")"),"#N/A") | D54: =IFERROR(__xludf.DUMMYFUNCTION("QUERY('โครงการ'!C65:J74,""SELECT I,J WHERE C IS NOT NULL"")"),"#N/A") | G54: FALSE | H54: FALSE
G55: FALSE | H55: FALSE
G56: FALSE | H56: FALSE
G57: FALSE | H57: FALSE
G58: FALSE | H58: FALSE
G59: FALSE | H59: FALSE
G60: FALSE | H60: FALSE
G61: FALSE | H61: FALSE
...

Sheet รายงานQ3
A7: แบบรายงานผลการดำเนินโครงการ ณ สิ้นสุดไตรมาส 3 ประจำปีงบประมาณ 2570
A8: หน่วยงาน | C8: ='โครงการ'!D4 | J8: คำอธิบายการกรอกแบบฟอร์ม
A9: ='โครงการ'!D6 | C9: ='โครงการ'!D7
A11: หัวหน้าโครงการ | C11: ='รายงานQ2'!C11 | F11: E-mail : @mfu | H11: ='รายงานQ2'!H11
A13: ชื่อผู้รายงานผล | F13: ผู้รายงานผลกรอกข้อมูลแล้วเสร็จ | J13: FALSE
A15: ณ สิ้นสุดไตรมาส ประเมินการดำเนินงานภาพรวมคิดเป็น | D15: ร้อยละ | E15: 0 | G15: =IFERROR(__xludf.DUMMYFUNCTION("IFERROR(SPARKLINE(E15,{""charttype"",""bar"";""color1"",""orenge"";""max"",100}),""โปรดระบุร้อยละการดำเนินงานเป็นตัวเลช"")"),"")
A17: หัวหน้าโครงการส่งรายงานผลการดำเนินงาน ณ สิ้นสุดไตรมาส 3 | E17: FALSE | G17: ว/ด/ป ที่ส่งรายงาน
A20: ผลการดำเนินงานรายกิจกรรม
A21: ลำดับที่ | B21: รหัสรายการ งบประมาณ | C21: ชื่อรายการงบประมาณ/ชื่อกิจกรรม | D21: สถานะ การดำเนินงาน | E21: อธิบายผลการดำเนินงานตามสถานะ (ให้ระบุว่า ณ สิ้นสุดไตรมาสมีการดำเนินงานอย่างไร)
A23: 1 | B23: =IFERROR(__xludf.DUMMYFUNCTION("QUERY('รายการงบประมาณ'!$A$2:$F80,""SELECT A,B WHERE E>0"")"),"#N/A")
A24: 2
A25: 3
A26: 4
A27: 5
A28: 6
A29: 7
A30: 8
A31: 9
A32: 10
A33: 11
A34: 12
A35: 13
... A42: 20
A43: คำอธิบาย สถานะการดำเนินงาน
A44: หมายเหตุ | B44: โปรดระบุตัวเลขสถานะการดำเนินงาน ในช่อง "สถานะการดำเนินงาน"
B45: 1 | C45: ไม่ได้ดำเนินงาน | D45: หมายถึง ถึงแผนที่จะต้องดำเนินงานแล้ว แต่ "ไม่ได้ดำเนินการ" เนื่องจากมีเหตุจำเป็น...
B46: 2 | C46: ไม่ถึงแผนที่กำหนด | D46: หมายถึง มีแผนการดำเนินงานในไตรมาสอื่น
B47: 3 | C47: อยู่ระหว่างการดำเนินงาน | D47: หมายถึง ดำเนินงานแล้ว แต่ยังไม่เเล้วเสร็จ หรือมีแผนดำเนินงานครั้งที่ 2/3/4
B48: 4 | C48: ดำเนินการแล้ว | D48: หมายถึง ดำเนินงานแล้วเสร็จ
A50: ผลการดำเนินงาน
A51: ตัวชี้วัดความสำเร็จของโครงการ | D51: หน่วยนับ | E51: แผน ปี 2570 | F51: ผล ปี 2570 | G51: การรายงานผล | I51: อธิบายผลการดำเนินงาน (รายงานผลเทียบแผน อย่างไร)
A53: เชิงปริมาณ | F53: ไตรมาส 3 | G53: ระบุได้ | H53: ระบุไม่ได้
A54: =IFERROR(__xludf.DUMMYFUNCTION("QUERY('โครงการ'!C65:J74,""SELECT C WHERE C IS NOT NULL"")"),"#N/A") | D54: =IFERROR(__xludf.DUMMYFUNCTION("QUERY('โครงการ'!C65:J74,""SELECT I,J WHERE C IS NOT NULL"")"),"#N/A") | G54: FALSE | H54: FALSE
G55: FALSE | H55: FALSE
G56: FALSE | H56: FALSE
G57: FALSE | H57: FALSE
G58: FALSE | H58: FALSE
G59: FALSE | H59: FALSE
G60: FALSE | H60: FALSE
G61: FALSE | H61: FALSE
...

Sheet รายงานQ4
A7: แบบรายงานผลการดำเนินโครงการ ณ สิ้นสุดไตรมาส 4 ประจำปีงบประมาณ 2570
A8: หน่วยงาน | C8: ='โครงการ'!D4 | J8: คำอธิบายการกรอกแบบฟอร์ม
A9: ='โครงการ'!D6 | C9: ='โครงการ'!D7
A11: หัวหน้าโครงการ | C11: ='รายงานQ3'!C11 | F11: E-mail : @mfu | H11: ='รายงานQ3'!H11
A13: ชื่อผู้รายงานผล | F13: ผู้รายงานผลกรอกข้อมูลแล้วเสร็จ | J13: FALSE
A15: ณ สิ้นสุดไตรมาส ประเมินการดำเนินงานภาพรวมคิดเป็น | D15: ร้อยละ | E15: 0 | G15: =IFERROR(__xludf.DUMMYFUNCTION("IFERROR(SPARKLINE(E15,{""charttype"",""bar"";""color1"",""orenge"";""max"",100}),""โปรดระบุร้อยละการดำเนินงานเป็นตัวเลช"")"),"")
A17: หัวหน้าโครงการส่งรายงานผลการดำเนินงาน ณ สิ้นสุดไตรมาส 4 | E17: FALSE | G17: ว/ด/ป ที่ส่งรายงาน
A20: ผลการดำเนินงานรายกิจกรรม
A21: ลำดับที่ | B21: รหัสรายการ งบประมาณ | C21: ชื่อรายการงบประมาณ/ชื่อกิจกรรม | D21: สถานะ การดำเนินงาน | E21: อธิบายผลการดำเนินงานตามสถานะ (ให้ระบุว่า ณ สิ้นสุดไตรมาสมีการดำเนินงานอย่างไร)
A23: 1 | B23: =IFERROR(__xludf.DUMMYFUNCTION("QUERY('รายการงบประมาณ'!$A$2:$F80,""SELECT A,B WHERE E>0"")"),"#N/A")
A24: 2
A25: 3
A26: 4
A27: 5
A28: 6
A29: 7
A30: 8
A31: 9
A32: 10
A33: 11
A34: 12
A35: 13
... A42: 20
A43: คำอธิบาย สถานะการดำเนินงาน
A44: หมายเหตุ | B44: โปรดระบุตัวเลขสถานะการดำเนินงาน ในช่อง "สถานะการดำเนินงาน"
B45: 1 | C45: ไม่ได้ดำเนินงาน | D45: หมายถึง ถึงแผนที่จะต้องดำเนินงานแล้ว แต่ "ไม่ได้ดำเนินการ" เนื่องจากมีเหตุจำเป็น...
B46: 2 | C46: ไม่ถึงแผนที่กำหนด | D46: หมายถึง มีแผนการดำเนินงานในไตรมาสอื่น
B47: 3 | C47: อยู่ระหว่างการดำเนินงาน | D47: หมายถึง ดำเนินงานแล้ว แต่ยังไม่เเล้วเสร็จ หรือมีแผนดำเนินงานครั้งที่ 2/3/4
B48: 4 | C48: ดำเนินการแล้ว | D48: หมายถึง ดำเนินงานแล้วเสร็จ
A50: ผลการดำเนินงาน
A51: ตัวชี้วัดความสำเร็จของโครงการ | D51: หน่วยนับ | E51: แผน ปี 2570 | F51: ผล ปี 2570 | G51: การรายงานผล | I51: อธิบายผลการดำเนินงาน (รายงานผลเทียบแผน อย่างไร)
A53: เชิงปริมาณ | F53: ไตรมาส 4 | G53: ระบุได้ | H53: ระบุไม่ได้
A54: =IFERROR(__xludf.DUMMYFUNCTION("QUERY('โครงการ'!C65:J74,""SELECT C WHERE C IS NOT NULL"")"),"#N/A") | D54: =IFERROR(__xludf.DUMMYFUNCTION("QUERY('โครงการ'!C65:J74,""SELECT I,J WHERE C IS NOT NULL"")"),"#N/A") | G54: FALSE | H54: FALSE
G55: FALSE | H55: FALSE
G56: FALSE | H56: FALSE
G57: FALSE | H57: FALSE
G58: FALSE | H58: FALSE
G59: FALSE | H59: FALSE
G60: FALSE | H60: FALSE
G61: FALSE | H61: FALSE
...

Sheet Final Report
A7: แบบรายงานผลปิดจบโครงการ (Final report) ประจำปีงบประมาณ 2570
A8: . | C8: ='โครงการ'!D4 | J8: คำอธิบายการกรอกแบบฟอร์ม
A9: ='โครงการ'!D6 | C9: ='โครงการ'!D7
A11: หัวหน้าโครงการ | C11: ='รายงานQ4'!C11 | F11: E-mail : @mfu | H11: ='รายงานQ4'!H11
A13: ชื่อผู้รายงานผล | F13: ผู้รายงานผลกรอกข้อมูลแล้วเสร็จ | J13: FALSE
A15: หัวหน้าโครงการส่งรายงานผลปิดจบโครงการ | E15: FALSE | G15: ว/ด/ป ที่ส่ง Final report
J16: J
A17: ส่วนนโยบายและแผน "ยืนยันรับ" รายงานผลปิดจบโครงการ | E17: FALSE | G17: ว/ด/ป ที่รับ Final report
A20: การดำเนินงาน-รายกิจกรรม | D20: รายรับ | F20: รายจ่าย | H20: การดำเนินงาน (ระบุเดือนที่ดำเนินการ) | J20: หมายเหตุ
A21: ลำดับที่ | B21: รหัสรายการ งบประมาณ | C21: ชื่อรายการงบประมาณ | D21: แผน | E21: ผล | F21: แผน | G21: ผล | H21: แผน | I21: ผล
A22: 1 | B22: =IFERROR(__xludf.DUMMYFUNCTION("QUERY('รายการงบประมาณ'!$A$2:$F244,""SELECT A,B WHERE E>0"")"),"#N/A") | F22: =IFERROR(__xludf.DUMMYFUNCTION("IFERROR(QUERY('รายการงบประมาณ'!$A$2:$F244,""SELECT E WHERE E>0""),"""")"),"")
A23: 2
A24: 3
A25: 4
A26: 5
A27: 6
A28: 7
A29: 8
A30: 9
A31: 10
A32: 11
A33: 12
A34: 13
... A41: 20
A43: ตัวชี้วัดความสำเร็จของโครงการ | D43: หน่วยนับ | E43: แผน ปี 2570 | F43: ผล ปี 2570 | G43: เอกสารแนบผลตัวชี้วัด | I43: *กรณีไม่สามารถแนบเอกสารได้โปรดระบุเหตุผล
I44: ค่าเฉลี่ยผลตัวชี้วัด
A45: เชิงปริมาณ | I45: =AVERAGE(I46:I55,I57:I66)
A46: =IFERROR(__xludf.DUMMYFUNCTION("QUERY('โครงการ'!C65:J74,""SELECT C WHERE C IS NOT NULL"")"),"#N/A") | D46: =IFERROR(__xludf.DUMMYFUNCTION("QUERY('โครงการ'!C65:J74,""SELECT I,J WHERE C IS NOT NULL"")"),"#N/A") | I46: =IF(A46="","",IF(IFERROR(F46/E46*100,"")>100,100,(F46/E46*100)))
I47: =IF(A47="","",IF(IFERROR(F47/E47*100,"")>100,100,(F47/E47*100)))
I48: =IF(A48="","",IF(IFERROR(F48/E48*100,"")>100,100,(F48/E48*100)))
I49: =IF(A49="","",IF(IFERROR(F49/E49*100,"")>100,100,(F49/E49*100)))
I50: =IF(A50="","",IF(IFERROR(F50/E50*100,"")>100,100,(F50/E50*100)))
I51: =IF(A51="","",IF(IFERROR(F51/E51*100,"")>100,100,(F51/E51*100)))
I52: =IF(A52="","",IF(IFERROR(F52/E52*100,"")>100,100,(F52/E52*100)))
I53: =IF(A53="","",IF(IFERROR(F53/E53*100,"")>100,100,(F53/E53*100)))
I54: =IF(A54="","",IF(IFERROR(F54/E54*100,"")>100,100,(F54/E54*100)))
I55: =IF(A55="","",IF(IFERROR(F55/E55*100,"")>100,100,(F55/E55*100)))
A56: เชิงคุณภาพ
A57: =IFERROR(__xludf.DUMMYFUNCTION("QUERY('โครงการ'!C76:J85,""SELECT C WHERE C IS NOT NULL"")"),"#N/A") | D57: =IFERROR(__xludf.DUMMYFUNCTION("QUERY('โครงการ'!C76:J85,""SELECT I,J WHERE C IS NOT NULL"")"),"#N/A") | I57: =IF(A57="","",IF(IFERROR(F57/E57*100,"")>100,100,(F57/E57*100)))
I58: =IF(A58="","",IF(IFERROR(F58/E58*100,"")>100,100,(F58/E58*100)))
...

Sheet เอกสารแนบ Final Report
A7: เอกสารแนบแบบรายงานผลปิดจบโครงการ (Final report) ประจำปีงบประมาณ 2570
A8: หน่วยงาน | C8: ='โครงการ'!D4
A9: ='โครงการ'!D6 | C9: ='โครงการ'!D7
A10: หัวหน้าโครงการ | C10: ='Final Report'!C11
A11: ชื่อผู้รายงานผล
A14: เอกสารแนบ
A15: รายการ | B15: รายละเอียด | D15: ลิ้งก์ไฟล์ใบเหลือง/ใบฟ้า
A16: 1
A17: 2
A18: 3
A19: 4
A20: 5
A22: ตัวอย่าง เอกสารแนบ (ใบเหลือง/ใบฟ้า) กรุณาเปิดสิทธิ์การเข้าถึงเอกสารแนบให้ budget.planning@mfu.ac.th
B23: หมายเหตุ (เพิ่มเติม)
B24: 1) กรณีไม่มีสัญญาเงินทดรองจ่าย (ใบเหลือง) หรือใบเบิกเงินสำรองจ่าย (ใบฟ้า) ให้หน่วยงานแนบเอกสาร “ขออนุมัติดำเนินงานโครงการหรืองาน" ที่ระบุระยะเวลาในการดำเนินงาน
B25: 2) กรณียกเลิก/คืนงบ ให้หน่วยงานแนบเอกสารบันทึกข้อความที่ได้ขอยกเลิก/คืนงบประมาณ พร้อมระบุเหตุผลให้ชัดเจน
B26: 3) กรณีขยายการดำเนินงาน หากดำเนินงานไม่แล้วเสร็จในปีงบประมาณนั้น จำนวนโครงการและงานดังกล่าวจะถูกนับรวมในปีงบประมาณถัดไป โดยให้หน่วยงานระบุเหตุผลให้ชัดเจน

Sheet Listความเชื่อมโยง
A1: แผนปฏิบัติการป้องกันการทุจริต แผนปฏิบัติการด้านการต่อต้านการทุจริตและประพฤติมิชอบ ระยะที่ 2 (พ.ศ.2566-2570) | F1: เป้าหมาย SDGs | K1: ความเชื่อมโยงกับค่านิยมองค์กร | N1: ประเด็นความเสี่ยง
A2: ประชาชนมีวัฒนธรรมและพฤติกรรมซื่อสัตย์สุจริต | B2: เป้าหมายที่ 1 | E2: =G2&" "&F2 | F2: ยุติความยากจน (No Poverty) | G2: SDG1 | K2: Flexibility ‘ปรับเปลี่ยน’ | N2: ความสามารถในการป้องกันภัยคุกคามทางไซเบอร์
A3: คดีทุจริตและประพฤติมิชอบลดลง | B3: เป้าหมายที่ 2 | E3: =G3&" "&F3 | F3: ขจัดความหิวโหย (Zero Hunger) | G3: SDG2 | K3: Integrity ‘ยึดมั่น’ | N3: ความสามารถในการปฏิบัติตามพระราชบัญญัติคุ้มครองข้อมูลส่วนบุคคล (PDPA)
A4: การดำเนินคดีทุจริตมีความรวดเร็ว เป็นธรรม โปร่งใส ไม่เลือกปฏิบัติ | B4: เป้าหมายที่ 3 | E4: =G4&" "&F4 | F4: สุขภาพและความเป็นอยู่ที่ดี (Good Health and Wellbeing) | G4: SDG3 | K4: Resourcefulness ‘สร้างสรรค์’ | N4: ความสามารถในการจัดการข้อมูลข่าวสารเชิงวิกฤตที่สร้างความเสียหายให้กับมหาวิทยาลัยในยุคดิจิทัล
E5: =G5&" "&F5 | F5: การศึกษาที่มีคุณภาพ (Quality Education) | G5: SDG4 | K5: Spirit ‘ด้วยใจ’ | N5: ความสามารถในการตอบสนองความคาดหวังของสังคม
E6: =G6&" "&F6 | F6: ความเท่าเทียมทางเพศ (Gender Equality) | G6: SDG5 | K6: Teamwork ‘ด้วยกัน’ | N6: ความสามารถในการพัฒนาบุคลากรให้สามารถปฏิบัติงานได้ตามความคาดหวัง ปรับตัวได้ทันต่อการเปลี่ยนแปลง และสามารถขับเคลื่อนมหาวิทยาลัยเข้าสู่การแข่งขันในอนาคต
E7: =G7&" "&F7 | F7: การจัดการน้ำ และสุขาภิบาล (Clean Water and Sanitation) | G7: SDG6 | N7: ความสามารถในการใช้ปัญญาประดิษฐ์อย่างเหมาะสมและมีประสิทธิภาพ
E8: =G8&" "&F8 | F8: พลังงานที่สะอาดและราคาย่อมเยา (Affordable and Clean Energy) | G8: SDG7 | N8: ความสามารถในการรับมือกับปัญหาสิ่งแวดล้อมและภัยพิบัติ
E9: =G9&" "&F9 | F9: การจ้างงานที่มีคุณค่าและการเติบโตทางเศรษฐกิจ (Decent Work and Economic Growth) | G9: SDG8 | N9: ความสามารถในการพึ่งพาตนเองด้านงบประมาณในระยะยาว
E10: =G10&" "&F10 | F10: อุตสาหกรรม นวัตกรรม และโครงสร้างพื้นฐาน (Industry, Innovation and Infrastructure) | G10: SDG9 | N10: ความสามารถในการดำเนินงานอย่างโปร่งใส ตรวจสอบได้ และการป้องกันการทุจริต ประพฤติมิชอบในมหาวิทยาลัย
E11: =G11&" "&F11 | F11: การลดความไม่เสมอภาค (Reduced Inequalities) | G11: SDG10
E12: =G12&" "&F12 | F12: เมืองและ ถิ่นฐานมนุษย์ที่ยั่งยืน (Sustainable Cities and Communities) | G12: SDG11
E13: =G13&" "&F13 | F13: การผลิตและการบริโภคอย่างมีความรับผิดชอบ (Responsible Consumption and Production) | G13: SDG12
E14: =G14&" "&F14 | F14: การรับมือกับการเปลี่ยนแปลงสภาพภูมิอากาศ (Climate Action) | G14: SDG13
E15: =G15&" "&F15 | F15: สิ่งมีชีวิตใต้น้ำ (Life below Water) | G15: SDG14
E16: =G16&" "&F16 | F16: สิ่งมีชีวิตบนบก (Life on Land) | G16: SDG15
E17: =G17&" "&F17 | F17: สังคมสงบสุข ยุติธรรม และสถาบันเข้มแข็ง (Peace, Justice and Strong Institutions) | G17: SDG16
E18: =G18&" "&F18 | F18: ความร่วมมือเพื่อการพัฒนาที่ยั่งยืน (Partnership for the Goals) | G18: SDG17

Sheet รายการงบประมาณ
A1: รหัสรายการ งบประมาณ | B1: ชื่อรายการงบประมาณ | C1: คำของบประมาณ (บาท) | D1: พิจารณางบประมาณ (บาท) | E1: จัดสรรงบประมาณ (บาท) | F1: USE
A2: =IFERROR(__xludf.DUMMYFUNCTION("IFERROR(ARRAYFORMULA(QUERY({TO_TEXT('งบประมาณ'!B11:B999),'งบประมาณ'!C11:C999,'งบประมาณ'!E11:E999,'งบประมาณ'!L11:L999,'งบประมาณ'!T11:T999,'งบประมาณ'!AG11:AG999},""SELECT * WHERE (Col3 > 0 OR Col5 > 0) AND Col6 IS NOT NULL"")))"),"")

Sheet REF
A1: Ref | B1: url | C1: Activate
A2: CodeFA-โครงการ | B2: https://docs.google.com/spreadsheets/d/1nIDy5zYDg9hGtVlnD76CI-o5uK9-d30d46_ROAe5vCk | C2: =IFERROR(__xludf.DUMMYFUNCTION("IMPORTRANGE(B2,""Connect!A1"")"),"Connect-FAโครงการปฏิบัติการ2570")
A3: CodeFP-โครงการ | B3: https://docs.google.com/spreadsheets/d/1g0zhpY87_t0kJRtMWN7xBQyYfoOAT1zgquATLTlLBNo | C3: =IFERROR(__xludf.DUMMYFUNCTION("IMPORTRANGE(B3,""Connect!A1"")"),"Connect-FPโครงการปฏิบัติการ2570")

Sheet Listคก.งาน
A1: วัน | B1: เดือน | C1: ปี | D1: แผนดำเนิงาน | F1: ลักษณะโครงการ | K1: งาน | M1: แผนงาน | N1: ประเภทโครงการ | O1: กลุ่มโครงการ | R1: แผนงาน | V1: Funds | W1: กองทุน | X1: Funds
A2: 01 | B2: 01 | C2: 2026 | D2: ต.ค.69 | F2: รายปี | G2: 01 | H2: A | J2: 01100 | K2: งานจัดการศึกษาสำนักวิชา | L2: 01100 | M2: 01 | N2: 1 | O2: 1Z | P2: 01100 | Q2: 01 | R2: แผนงานการเรียนการสอน | S2: 01 | T2: 1 | V2: 201000 | W2: กองทุนทั่วไป | X2: 201000
A3: 02 | B3: 02 | C3: 2027 | D3: พ.ย.69 | F3: โครงการต่อเนื่อง | G3: 21 | H3: P | J3: 01102 | K3: งานสนับสนุนการจัดการศึกษา | L3: 01102 | M3: 01 | N3: 1 | O3: 1Z | P3: 01102 | Q3: 02 | R3: แผนงานวิจัย | S3: 02 | T3: 2 | V3: 202000 | W3: กองทุนเพื่อการศึกษา | X3: 202000
A4: 03 | B4: 03 | D4: ธ.ค.69 | F4: โครงการงบประมาณแผ่นดิน | G4: 31 | H4: T | J4: 01103 | K4: งานบริหารและจัดการหลักสูตรพิเศษ | L4: 01103 | M4: 01 | N4: 1 | O4: 1Z | P4: 01103 | Q4: 03 | R4: แผนงานบริการวิชาการแก่สังคม | S4: 03 | T4: 3 | V4: 203000 | W4: กองทุนวิจัย | X4: 203000
A5: 04 | B5: 04 | D5: ม.ค.70 | J5: 01104 | K5: งานพัฒนาความสัมพันธ์ระหว่างประเทศ | L5: 01104 | M5: 01 | N5: 1 | O5: 1Z | P5: 01104 | Q5: 04 | R5: แผนงานศาสนา ศิลปวัฒนธรรมและสิ่งแวดล้อม | S5: 04 | T5: 4 | V5: 204000 | W5: กองทุนบริการวิชาการแก่สังคม | X5: 204000
A6: 05 | B6: 05 | D6: ก.พ.70 | J6: 01105 | K6: งานพัฒนาทักษะนักศึกษา | L6: 01105 | M6: 01 | N6: 1 | O6: 1Z | P6: 01105 | Q6: 05 | R6: แผนงานสนับสนุนวิชาการ | S6: 05 | T6: 5 | V6: 205000 | W6: กองทุนสินทรัพย์ถาวร | X6: 205000
A7: 06 | B7: 06 | D7: มี.ค.70 | J7: 02201 | K7: งานวิจัย พัฒนาและถ่ายทอดเทคโนโลยี | L7: 02201 | M7: 02 | N7: 2 | O7: 2Z | P7: 02201 | Q7: 06 | R7: แผนงานบริหารมหาวิทยาลัย | S7: 06 | T7: 6 | V7: 206000 | W7: กองทุนกิจกรรมนักศึกษา | X7: 206000
A8: 07 | B8: 07 | D8: เม.ย.70 | J8: 02202 | K8: หน่วยวิจัยเฉพาะทาง | L8: 02202 | M8: 02 | N8: 2 | O8: 2Z | P8: 02202 | Q8: 07 | R8: แผนงานบริการสุขภาพแก่สังคม | S8: 07 | T8: 7 | V8: 207001 | W8: กองทุนทำนุบำรุงศิลปวัฒนธรรม | X8: 207001
A9: 08 | B9: 08 | D9: พ.ค.70 | J9: 03301 | K9: งานบริการวิชาการแก่สังคม | L9: 03301 | M9: 03 | N9: 3 | O9: 3Z | P9: 03301 | V9: 207002 | W9: กองทุนบริการสุขภาพแก่สังคม | X9: 207002
A10: 09 | B10: 09 | D10: มิ.ย.70 | F10: ลักษณะงาน | J10: 04401 | K10: งานทำนุบำรุง ศิลปวัฒนธรรมและสิ่งแวดล้อม | L10: 04401 | M10: 04 | N10: 4 | O10: 4Z | P10: 04401 | V10: 207003 | W10: กองทุนส่งเสริมการพัฒนาบุคลากร | X10: 207003
A11: 10 | B11: 10 | D11: ก.ค.70 | F11: รายปี-ต้นปี | G11: 01 | H11: B | J11: 05501 | K11: งานบริการเครื่องมือวิทยาศาสตร์และเทคโนโลยี | L11: 05501 | M11: 05 | N11: 5 | O11: 5Z | P11: 05501 | V11: 207999 | W11: กองทุนสำรองทั่วไป | X11: 207999
A12: 11 | B12: 11 | D12: ส.ค.70 | F12: รายปี-ระหว่างปี | G12: 03 | H12: B | J12: 05502 | K12: งานบริการห้องสมุดและสื่อการศึกษา | L12: 05502 | M12: 05 | N12: 5 | O12: 5Z | P12: 05502
A13: 12 | B13: 12 | D13: ก.ย.70 | F13: งานภายใต้งบประมาณแผ่นดิน | G13: 32 | H13: U | J13: 05503 | K13: งานบริการเทคโนโลยีสารสนเทศ | L13: 05503 | M13: 05 | N13: 5 | O13: 5Z | P13: 05503
A14: 13 | J14: 06601 | K14: งานบริหารทั่วไป | L14: 06601 | M14: 06 | N14: 6 | O14: 6Z | P14: 06601
A15: 14 | J15: 06602 | K15: งานจัดหารายได้ | L15: 06602 | M15: 06 | N15: 6 | O15: 6Z | P15: 06602
A16: 15 | J16: 06603 | K16: งานตรวจสอบภายใน | L16: 06603 | M16: 06 | N16: 6 | O16: 6Z | P16: 06603
A17: 16 | J17: 06604 | K17: งานกิจการสภามหาวิทยาลัย | L17: 06604 | M17: 06 | N17: 6 | O17: 6Z | P17: 06604
A18: 17 | J18: 06605 | K18: งานส่งเสริมธรรมาภิบาลและความโปร่งใสในการดำเนินงาน | L18: 06605 | M18: 06 | N18: 6 | O18: 6Z | P18: 06605
A19: 18 | J19: 06606 | K19: การสร้างความผูกพันในองค์กร | L19: 06606 | M19: 06 | N19: 6 | O19: 6Z | P19: 06606
A20: 19 | J20: 07700 | K20: งานให้บริการรักษาพยาบาลเเละส่งเสริมสุขภาพเพื่อการศึกษาเเละวิจัย | L20: 07700 | M20: 07 | N20: 7 | O20: 7Z | P20: 07700
A21: 20
A22: 21
A23: 22
A24: 23 | K24: รายปี-ระหว่างปี | L24: 03 | M24: A
A25: 24 | K25: โครงการเดิม/ต่อเนื่อง-ระหว่างปี | L25: 23 | M25: P
A26: 25 | K26: โครงการได้รับเงินสนับสนุนจากภายนอก | L26: 33 | M26: D
A27: 26 | K27: โครงการเงินยุทธศาสตร์การพัฒนามหาวิทยาลัย | L27: 34 | M27: F
A28: 27 | K28: โครงการเงินสำรองจ่าย | L28: 35 | M28: G
A29: 28
A30: 29 | J30: รหัสงาน | K30: แผนปฏิบัติงาน | L30: Funds | M30: กองทุน
A31: 30 | J31: 01100 | K31: งานจัดการศึกษาสำนักวิชา | L31: 202000 | M31: กองทุนเพื่อการศึกษา
A32: 31 | J32: 01102 | K32: งานสนับสนุนการจัดการศึกษา | L32: 202000 | M32: กองทุนเพื่อการศึกษา
J33: 01103 | K33: งานบริหารและจัดการหลักสูตรพิเศษ | L33: 202000 | M33: กองทุนเพื่อการศึกษา
J34: 01104 | K34: งานพัฒนาความสัมพันธ์ระหว่างประเทศ | L34: 202000 | M34: กองทุนเพื่อการศึกษา
J35: 02201 | K35: งานวิจัย พัฒนาและถ่ายทอดเทคโนโลยี | L35: 203000 | M35: กองทุนวิจัย
J36: 02202 | K36: หน่วยวิจัยเฉพาะทาง | L36: 203000 | M36: กองทุนวิจัย
J37: 03301 | K37: งานบริการวิชาการแก่สังคม | L37: 204000 | M37: กองทุนบริการวิชาการแก่สังคม
J38: 04401 | K38: งานทำนุบำรุง ศิลปวัฒนธรรมและสิ่งแวดล้อม | L38: 207001 | M38: กองทุนทำนุบำรุงศิลปวัฒนธรรม
J39: 05501 | K39: งานบริการเครื่องมือวิทยาศาสตร์และเทคโนโลยี | L39: 202000 | M39: กองทุนเพื่อการศึกษา
J40: 05502 | K40: งานบริการห้องสมุดและสื่อการศึกษา | L40: 202000 | M40: กองทุนเพื่อการศึกษา
...

Sheet ListFP
A1: ประเภท | B1: FP-70 | C1: รายการงบประมาณ | D1: CI | E1: ชื่อบัญชีงบประมาณ | F1: รหัสหมวดเงิน | G1: ชื่อหมวดเงิน
A2: FP-GL | B2: 7033101 | C2: เงินค่าอาหารทำการนอกเวลา สำหรับพนักงาน | D2: 6201010001 | E2: =C2 | F2: 5300 | G2: หมวดตอบแทน ใช้สอยและวัสดุ
A3: FP-GL | B3: 7033310 | C3: เงินค่าอาหารทำการนอกเวลา สำหรับลูกจ้างชั่วคราวรายเดือน | D3: 6201010002 | E3: =C3 | F3: 5300 | G3: หมวดตอบแทน ใช้สอยและวัสดุ
A4: FP-GL | B4: 7033311 | C4: เงินค่าอาหารทำการนอกเวลา สำหรับลูกจ้างชั่วคราวรายวัน | D4: 6201010003 | E4: =C4 | F4: 5300 | G4: หมวดตอบแทน ใช้สอยและวัสดุ
A5: FP-GL | B5: 7033312 | C5: เงินค่าอาหารทำการนอกเวลา สำหรับพนักงานขับรถ | D5: 6201010004 | E5: =C5 | F5: 5300 | G5: หมวดตอบแทน ใช้สอยและวัสดุ
A6: FP-GL | B6: 7033002 | C6: ค่าเบี้ยประชุม | D6: 6201020001 | E6: =C6 | F6: 5300 | G6: หมวดตอบแทน ใช้สอยและวัสดุ
A7: FP-GL | B7: 7033003 | C7: ค่าตอบแทนกรรมการประชุมอื่นๆ | D7: 6201020002 | E7: =C7 | F7: 5300 | G7: หมวดตอบแทน ใช้สอยและวัสดุ
A8: FP-GL | B8: 7033112 | C8: ค่าตอบแทนผู้ตรวจสอบบัญชี | D8: 6201020003 | E8: =C8 | F8: 5300 | G8: หมวดตอบแทน ใช้สอยและวัสดุ
A9: FP-GL | B9: 7033004 | C9: ค่าตอบแทนอาจารย์พิเศษ | D9: 6201020005 | E9: =C9 | F9: 5300 | G9: หมวดตอบแทน ใช้สอยและวัสดุ
A10: FP-GL | B10: 7033005 | C10: ค่าตอบแทนอาจารย์ประสานงาน | D10: 6201020006 | E10: =C10 | F10: 5300 | G10: หมวดตอบแทน ใช้สอยและวัสดุ
A11: FP-GL | B11: 7033113 | C11: ค่าตอบแทนผู้ช่วยสอน | D11: 6201020007 | E11: =C11 | F11: 5300 | G11: หมวดตอบแทน ใช้สอยและวัสดุ
A12: FP-GL | B12: 7033114 | C12: ค่าตอบแทนแพทย์ | D12: 6201020008 | E12: =C12 | F12: 5300 | G12: หมวดตอบแทน ใช้สอยและวัสดุ
A13: FP-GL | B13: 7033006 | C13: ค่าตอบแทนอาจารย์ผู้ควบคุมฝึกปฏิบัติงาน นศ. | D13: 6201020009 | E13: =C13 | F13: 5300 | G13: หมวดตอบแทน ใช้สอยและวัสดุ
... A255: FP-GL | B255: 7033496 | C255: ค่าที่พักอาจารย์-ฝึกอบรมบุคคลภายนอก | D255: 6202500053 | E255: =C255 | F255: 5300 | G255: หมวดตอบแทน ใช้สอยและวัสดุ

Sheet ListCost_Center
A1: รหัส FC | B1: หน่วยงาน | C1: รหัสงาน | D1: ชื่องาน | E1: รหัสกองทุน | F1: กองทุน
B2: #กลุ่มสำนักวิชา
A3: 11100000 | B3: สำนักวิชาศิลปศาสตร์ | C3: 01100 | D3: งานจัดการศึกษาสำนักวิชา | E3: 202000 | F3: กองทุนเพื่อการศึกษา
A4: 11110000 | B4: สำนักวิชาวิทยาศาสตร์ | C4: 01100 | D4: งานจัดการศึกษาสำนักวิชา | E4: 202000 | F4: กองทุนเพื่อการศึกษา
A5: 11120000 | B5: สำนักวิชาการจัดการ | C5: 01100 | D5: งานจัดการศึกษาสำนักวิชา | E5: 202000 | F5: กองทุนเพื่อการศึกษา
A6: 11130000 | B6: สำนักวิชาเทคโนโลยีดิจิทัลประยุกต์ | C6: 01100 | D6: งานจัดการศึกษาสำนักวิชา | E6: 202000 | F6: กองทุนเพื่อการศึกษา
A7: 11140000 | B7: สำนักวิชาอุตสาหกรรมเกษตร | C7: 01100 | D7: งานจัดการศึกษาสำนักวิชา | E7: 202000 | F7: กองทุนเพื่อการศึกษา
A8: 11160000 | B8: สำนักวิชานิติศาสตร์ | C8: 01100 | D8: งานจัดการศึกษาสำนักวิชา | E8: 202000 | F8: กองทุนเพื่อการศึกษา
A9: 11170000 | B9: สำนักวิชาวิทยาศาสตร์เครื่องสำอาง | C9: 01100 | D9: งานจัดการศึกษาสำนักวิชา | E9: 202000 | F9: กองทุนเพื่อการศึกษา
A10: 11180000 | B10: สำนักวิชาวิทยาศาสตร์สุขภาพ | C10: 01100 | D10: งานจัดการศึกษาสำนักวิชา | E10: 202000 | F10: กองทุนเพื่อการศึกษา
A11: 11190000 | B11: สำนักวิชาพยาบาลศาสตร์ | C11: 01100 | D11: งานจัดการศึกษาสำนักวิชา | E11: 202000 | F11: กองทุนเพื่อการศึกษา
A12: 11200000 | B12: สำนักวิชาเวชศาสตร์ชะลอวัยและฟื้นฟูสุขภาพ | C12: 01100 | D12: งานจัดการศึกษาสำนักวิชา | E12: 202000 | F12: กองทุนเพื่อการศึกษา
A13: 11210000 | B13: สำนักวิชาแพทยศาสตร์ | C13: 01100 | D13: งานจัดการศึกษาสำนักวิชา | E13: 202000 | F13: กองทุนเพื่อการศึกษา
A14: 11220000 | B14: สำนักวิชาทันตแพทยศาสตร์ | C14: 01100 | D14: งานจัดการศึกษาสำนักวิชา | E14: 202000 | F14: กองทุนเพื่อการศึกษา
... A21: 11250000 | B21: สำนักวิชาการแพทย์บูรณาการ | C21: 01100 | D21: งานจัดการศึกษาสำนักวิชา | E21: 202000 | F21: กองทุนเพื่อการศึกษา
B22: #กลุ่มศูนย์
A23: 11600000 | B23: ศูนย์บริการเทคโนโลยีสารสนเทศ | C23: 05503 | D23: งานบริการเทคโนโลยีสารสนเทศ | E23: 202000 | F23: กองทุนเพื่อการศึกษา
A24: 11610000 | B24: ศูนย์เครื่องมือวิทยาศาสตร์และเทคโนโลยี | C24: 05501 | D24: งานบริการเครื่องมือวิทยาศาสตร์และเทคโนโลยี | E24: 202000 | F24: กองทุนเพื่อการศึกษา
A25: 11620000 | B25: ศูนย์บรรณสารและสื่อการศึกษา | C25: 05502 | D25: งานบริการห้องสมุดและสื่อการศึกษา | E25: 202000 | F25: กองทุนเพื่อการศึกษา
A26: 11640000 | B26: ศูนย์บริการวิชาการ | C26: 03301 | D26: งานบริการวิชาการแก่สังคม | E26: 204000 | F26: กองทุนบริการวิชาการแก่สังคม
A27: 11407001 | B27: สถาบันอนุรักษ์ พัฒนาทรัพยากรธรรมชาติและสิ่งแวดล้อม เพื่อความยั่งยืน | C27: 06601 | D27: งานบริหารทั่วไป | E27: 201000 | F27: กองทุนทั่วไป
A28: 11870000 | B28: โรงพยาบาลศูนย์การแพทย์มหาวิทยาลัยแม่ฟ้าหลวง
B29: #กลุ่มสถาบัน
A30: 11890000 | B30: สถาบันวิจัยและนวัตกรรม มหาวิทยาลัยแม่ฟ้าหลวง | C30: 01102 | D30: งานสนับสนุนการจัดการศึกษา | E30: 203000 | F30: กองทุนวิจัย
A31: 11412000 | B31: ส่วนบริหารงานวิจัย | C31: 02201 | D31: งานวิจัย พัฒนาและถ่ายทอดเทคโนโลยี | E31: 203000 | F31: กองทุนวิจัย
A32: 11411100 | B32: ส่วนจัดการทรัพย์สินทางปัญญาและนวัตกรรม | C32: 02202 | D32: หน่วยวิจัยเฉพาะทาง | E32: 203000 | F32: กองทุนวิจัย
A33: 11820000 | B33: สถาบันศิลปวัฒนธรรมและอารยธรรมลุ่มน้ำโขง | C33: 04401 | D33: งานทำนุบำรุง ศิลปวัฒนธรรมและสิ่งแวดล้อม | E33: 204000 | F33: กองทุนบริการวิชาการแก่สังคม
A34: 11710000 | B34: สถาบันนวัตกรรมการเรียนรู้มหาวิทยาลัยแม่ฟ้าหลวง | C34: 01102 | D34: งานสนับสนุนการจัดการศึกษา | E34: 202000 | F34: กองทุนเพื่อการศึกษา
B35: #กลุ่มสำนักงานวิชาการ
A36: 11411000 | B36: ส่วนทะเบียนและประมวลผล | C36: 01102 | D36: งานสนับสนุนการจัดการศึกษา | E36: 202000 | F36: กองทุนเพื่อการศึกษา
A37: 11413000 | B37: ส่วนพัฒนานักศึกษา | C37: 01102 | D37: งานสนับสนุนการจัดการศึกษา | E37: 206000 | F37: กองทุนกิจกรรมนักศึกษา
A38: 11414000 | B38: ส่วนพัฒนาความสัมพันธ์ระหว่างประเทศ | C38: 01104 | D38: งานพัฒนาความสัมพันธ์ระหว่างประเทศ | E38: 202000 | F38: กองทุนเพื่อการศึกษา
A39: 11415000 | B39: ส่วนประกันคุณภาพการศึกษาและพัฒนาหลักสูตร | C39: 01102 | D39: งานสนับสนุนการจัดการศึกษา | E39: 202000 | F39: กองทุนเพื่อการศึกษา
A40: 11416000 | B40: สำนักงานบัณฑิตศึกษา | C40: 01103 | D40: งานบริหารและจัดการหลักสูตรพิเศษ | E40: 202000 | F40: กองทุนเพื่อการศึกษา
A41: 11417000 | B41: ส่วนจัดหางานและฝึกงานของนักศึกษา | C41: 01102 | D41: งานสนับสนุนการจัดการศึกษา | E41: 202000 | F41: กองทุนเพื่อการศึกษา
A42: 11413300 | B42: สำนักงานให้คำปรึกษาและช่วยเหลือนักศึกษา | C42: 01102 | D42: งานสนับสนุนการจัดการศึกษา | E42: 206000 | F42: กองทุนกิจกรรมนักศึกษา
A43: 11413200 | B43: ศูนย์กีฬามหาวิทยาลัยแม่ฟ้าหลวง | C43: 01102 | D43: งานสนับสนุนการจัดการศึกษา | E43: 202000 | F43: กองทุนเพื่อการศึกษา
A44: 11418000 | B44: สถาบันชาและกาแฟ แห่งมหาวิทยาลัยแม่ฟ้าหลวง | C44: 02202 | D44: หน่วยวิจัยเฉพาะทาง | E44: 203000 | F44: กองทุนวิจัย
A45: 11180008 | B45: ศูนย์นวัตกรรมสมุนไพรครบวงจร มหาวิทยาลัยแม่ฟ้าหลวง | C45: 02202 | D45: หน่วยวิจัยเฉพาะทาง | E45: 203000 | F45: กองทุนวิจัย
A46: 11860000 | B46: โครงการจัดตั้งศูนย์ส่งเสริมและพัฒนาธุรกิจ SMEs เครื่องสำอางไทย มหาวิทยาลัยแม่ฟ้าหลวง | C46: 02201 | D46: งานวิจัย พัฒนาและถ่ายทอดเทคโนโลยี | E46: 203000 | F46: กองทุนวิจัย
...

Sheet List-KPI
A1: กลยุทธ์แผนพัฒนาฉบับที่ 5 | B1: ='โครงการ'!D13
A2: ตัวชี้วัด(X) | B2: =IFERROR(__xludf.DUMMYFUNCTION("UNIQUE(QUERY(dropdown_plan6!A:R,""SELECT R WHERE O ='""&B1&""'""))"),"")

Sheet dropdown_plan6
A1: ยุทธศาสตร์ | B1: ชื่อยุทธศาสตร์ | C1: ชื่อเต็มยุทธศาสตร์ | D1: เป้าประสงค์ | E1: ZKPI | F1: ชื่อตัวชี้วัดของยุทธศาสตร์ | G1: ชื่อเต็มตัวชี้วัดของยุทธศาสตร์ | H1: รหัสประเด็นยุทธศาสตร์ | I1: ชื่อประเด็นยุทธศาสตร์ | J1: ชื่อเต็มประเด็นยุทธศาสตร์ | K1: เป้าหมายประเด็นยุทธศาสตร์ | L1: YKPI | M1: ชื่อตัวชี้วัดประเด็นยุทธศาสตร์ | N1: ชื่อเต็มตัวชี้วัดประเด็นยุทธศาสตร์ | O1: กลยุทธ์ (T) | P1: XKPI | Q1: ชื่อตัวชี้วัดกระบวนการ | R1: ชื่อเต็มตัวชี้วัดกระบวนการ
